[2024-02-29 16:19:45,285 INFO] Use GPU: None for training
[2024-02-29 16:19:45,285 INFO] 

[2024-02-29 16:19:47,523 INFO] Total params: 109.04M
[2024-02-29 16:20:02,893 INFO] acc: 0.90
[2024-02-29 16:20:02,909 INFO] Victim model accuracy = 0.9016, spec = 0.90, sens = 0.93
[2024-02-29 16:20:02,910 INFO] Loading thief dataset ...
[2024-02-29 16:20:02,912 INFO] 
Initializing thief model ...


Loaded supervised labeled set of length  900
Labeled set expanded to length  900 , unique indices  900
dataset root /home/deepankar/mnt/vision3_data_ckpts_msa_medical/GBUSV-Shared
Num of videos 64 frames 15800
15800
15800
Num of videos 64 frames 15800
  0%|          | 0/8 [00:00<?, ?it/s] 12%|█▎        | 1/8 [00:10<01:13, 10.47s/it] 25%|██▌       | 2/8 [00:13<00:35,  5.89s/it] 38%|███▊      | 3/8 [00:18<00:27,  5.55s/it] 50%|█████     | 4/8 [00:20<00:17,  4.41s/it] 62%|██████▎   | 5/8 [00:24<00:11,  3.93s/it] 75%|███████▌  | 6/8 [00:27<00:07,  3.62s/it] 88%|████████▊ | 7/8 [00:29<00:03,  3.38s/it]100%|██████████| 8/8 [00:31<00:00,  2.87s/it]100%|██████████| 8/8 [00:31<00:00,  3.98s/it]
Num of videos 64 frames 15800
  0%|          | 0/1 [00:00<?, ?it/s]100%|██████████| 1/1 [00:05<00:00,  5.93s/it]100%|██████████| 1/1 [00:06<00:00,  6.04s/it]
[2024-02-29 16:20:40,889 INFO] unlabeled data number: 15800, labeled data number 900
[2024-02-29 16:20:40,890 INFO] Create train and test data loaders
[2024-02-29 16:20:40,890 INFO] [!] data loader keys: dict_keys(['train_lb', 'train_ulb', 'eval', 'test'])
[2024-02-29 16:20:41,820 INFO] Create optimizer and scheduler
[2024-02-29 16:20:41,828 INFO] Number of Trainable Params: 23514179
Num of videos 64 frames 15800
Load pretrained model for initializing the thief from  /home/deepankar/mnt/vision3_data_ckpts_msa_medical/ckpts/resnet50-imagenet1k.pth
key not found fc.weight
key not found fc.bias
Common keys pretrained model:  318
Load anchor model /home/deepankar/scratch/MSA_Medical/results_1k/gbusg_radformer/GBUSV_resnet50/SGD/1000_val100/random_v1_0.005_transforms/trial_1_cycle_1_best.pth
thief state:  ['conv1.weight', 'bn1.weight', 'bn1.bias', 'bn1.running_mean', 'bn1.running_var']
pretrained state:  ['conv1.weight', 'bn1.weight', 'bn1.bias', 'bn1.running_mean', 'bn1.running_var']
Common keys anchor model:  320
[2024-02-29 16:20:52,091 INFO] Anchor model on target dataset: acc = 0.6557, spec = 0.85, sens = 0.62
[2024-02-29 16:20:52,588 INFO] Arguments: Namespace(T=0.5, algorithm='selfkd', amp=False, batch_size=16, c='configs/gbc/selfkd.yaml', clip=0.0, clip_grad=0, crop_ratio=0.875, data_dir='./data', dataset='GBUSV', device=device(type='cuda'), dist_backend='nccl', dist_url='tcp://127.0.0.1:21411', distributed=False, ds_seed=123, ema_m=0.999, epoch=100, eval_batch_size=16, eval_step=234, expand_labels=True, gpu=None, hard_label=True, imb_algorithm=None, img_size=224, include_lb_to_ulb=True, kd_alpha=0.4, kd_alpha_ulb=0.5, kd_temp=1.5, kd_temp_ulb=1.5, la=False, labeled_set_path='/home/deepankar/scratch/MSA_Medical/results_1k/gbusg_radformer/GBUSV_resnet50/SGD/1000_val100/random_v1_0.005_transforms/X_trial_1_cycle_1_labeled_set.npy', layer_decay=0.5, lb_dest_len=900, lb_imb_ratio=1, load_labeled_set=True, load_path=None, local_rank=-1, lr=0.02, max_length=512, max_length_seconds=4.0, momentum=0.9, multiprocessing_distributed=False, net='resnet50', net_from_name=False, no_progress=True, num_classes=3, num_eval_iter=234, num_labels=5000, num_log_iter=234, num_train_iter=900000, num_warmup_iter=5120, num_workers=4, optim='SGD', overwrite=True, p_cutoff=0.95, pretrain_path='', pretrained_dir='/home/deepankar/mnt/vision3_data_ckpts_msa_medical/ckpts/resnet50-imagenet1k.pth', rank=0, resume=False, sample_rate=16000, save_dir='saved_models/radformer', save_name='selfkd_v8_exp2', scheduler_type='cosine', seed=5, subset=128116, thief_root='/home/deepankar/mnt/vision3_data_ckpts_msa_medical/GBUSV-Shared', train_sampler='RandomSampler', tro=1, ulb_dest_len=15800, ulb_imb_ratio=1, ulb_loss_ratio=1.0, ulb_num_labels=None, uratio=7, use_aim=False, use_cat=True, use_pretrain=True, use_tensorboard=True, use_wandb=True, val_set_path='/home/deepankar/scratch/MSA_Medical/results_1k/gbusg_radformer/GBUSV_resnet50/SGD/1000_val100/random_v1_0.005_transforms/X_trial_1_cycle_1_val_set.npy', victim_arch='radformer', victim_data_root='/home/deepankar/mnt/vision3_data_ckpts_msa_medical/GBCU-Shared', victim_dataset='gbusg', victim_model_path='/home/deepankar/mnt/vision3_data_ckpts_msa_medical/victim_models/radformer/radformer.pkl', warmstart=False, warmstart_dir='/home/deepankar/scratch/MSA_Medical/results_1k/gbusg_radformer/GBUSV_resnet50/SGD/1000_val100/random_v1_0.005_transforms/trial_1_cycle_1_best.pth', warmup=0, warmup_epoch=10, weight_decay=0.0005, world_size=1)
[2024-02-29 16:20:52,588 INFO] Validation set distribution: 
anchor model temp =  1.0
Number of samples  100
[2024-02-29 16:20:53,531 INFO] {0: 9, 1: 18, 2: 73}
[2024-02-29 16:20:53,531 INFO] Labeled set distribution: 
Number of samples  900
[2024-02-29 16:20:56,413 INFO] {0: 111, 1: 199, 2: 586}
[2024-02-29 16:21:02,189 INFO] Initial model on target dataset (without EMA): acc = 0.3934, agreement = 0.3770, spec = 0.42, sens = 0.55
[2024-02-29 16:21:02,189 INFO] Resume load path None does not exist
[2024-02-29 16:21:02,189 INFO] 
Model training
wandb: Currently logged in as: satwikdpshrit. Use `wandb login --relogin` to force relogin
wandb: - Waiting for wandb.init()...wandb: \ Waiting for wandb.init()...wandb: Tracking run with wandb version 0.16.3
wandb: Run data is saved locally in saved_models/radformer/wandb/selfkd_v8_exp2/wandb/run-20240229_162104-sax7xdet
wandb: Run `wandb offline` to turn off syncing.
wandb: Syncing run selfkd_v8_exp2
wandb: ⭐️ View project at https://wandb.ai/satwikdpshrit/radformer
wandb: 🚀 View run at https://wandb.ai/satwikdpshrit/radformer/runs/sax7xdet
[2024-02-29 16:21:08,950 INFO] 

epoch 0
[2024-02-29 16:22:15,796 INFO] validating...
[2024-02-29 16:22:20,308 INFO] model saved: saved_models/radformer/selfkd_v8_exp2/latest_model.pth
[2024-02-29 16:22:20,862 INFO] model saved: saved_models/radformer/selfkd_v8_exp2/model_best.pth
[2024-02-29 16:22:20,863 INFO] 57 iteration, USE_EMA: True, train/sup_loss: 1.30154, train/unsup_loss: 0.75252, train/total_loss: 2.05406, train/util_ratio: 0.66071, train/run_time: 0.95140, lr: 0.00000, train/prefecth_time: 0.04746, eval/loss: 1.13220, eval/top-1-acc: 0.25000, eval/balanced_acc: 0.30923, eval/precision: 0.32497, eval/recall: 0.30923, eval/F1: 0.23045, eval/spec: 0.77778, eval/sens: 0.20548, test/loss: 1.09565, test/top-1-acc: 0.36885, test/balanced_acc: 0.34463, test/precision: 0.36119, test/recall: 0.34463, test/F1: 0.30840, test/spec: 0.40000, test/sens: 0.64286 BEST_EVAL_ACC: 0.2500, at 57 iters BEST_TEST_ACC: 0.3689, at 57 iters
[2024-02-29 16:22:20,868 INFO] 

epoch 1
[2024-02-29 16:23:23,400 INFO] validating...
[2024-02-29 16:23:28,534 INFO] model saved: saved_models/radformer/selfkd_v8_exp2/latest_model.pth
[2024-02-29 16:23:29,442 INFO] model saved: saved_models/radformer/selfkd_v8_exp2/model_best.pth
[2024-02-29 16:23:29,443 INFO] 113 iteration, USE_EMA: True, train/sup_loss: 0.90942, train/unsup_loss: 0.51212, train/total_loss: 1.42154, train/util_ratio: 0.67857, train/run_time: 0.95706, lr: 0.00200, train/prefecth_time: 0.03556, eval/loss: 1.04579, eval/top-1-acc: 0.56000, eval/balanced_acc: 0.37189, eval/precision: 0.37738, eval/recall: 0.37189, eval/F1: 0.37149, eval/spec: 0.40741, eval/sens: 0.67123, test/loss: 1.09050, test/top-1-acc: 0.34426, test/balanced_acc: 0.32540, test/precision: 0.24837, test/recall: 0.32540, test/F1: 0.22944, test/spec: 0.12500, test/sens: 0.83333 BEST_EVAL_ACC: 0.5600, at 113 iters BEST_TEST_ACC: 0.3443, at 113 iters
[2024-02-29 16:23:29,448 INFO] 

epoch 2
[2024-02-29 16:24:32,361 INFO] validating...
[2024-02-29 16:24:37,308 INFO] model saved: saved_models/radformer/selfkd_v8_exp2/latest_model.pth
[2024-02-29 16:24:38,093 INFO] model saved: saved_models/radformer/selfkd_v8_exp2/model_best.pth
[2024-02-29 16:24:38,096 INFO] 169 iteration, USE_EMA: True, train/sup_loss: 0.66529, train/unsup_loss: 0.45214, train/total_loss: 1.11742, train/util_ratio: 0.63393, train/run_time: 0.95611, lr: 0.00400, train/prefecth_time: 0.02614, eval/loss: 0.97806, eval/top-1-acc: 0.75000, eval/balanced_acc: 0.49112, eval/precision: 0.59921, eval/recall: 0.49112, eval/F1: 0.52040, eval/spec: 0.37037, eval/sens: 0.91781, test/loss: 1.08765, test/top-1-acc: 0.38525, test/balanced_acc: 0.35941, test/precision: 0.29848, test/recall: 0.35941, test/F1: 0.27700, test/spec: 0.18750, test/sens: 0.83333 BEST_EVAL_ACC: 0.7500, at 169 iters BEST_TEST_ACC: 0.3852, at 169 iters
[2024-02-29 16:24:38,100 INFO] 

epoch 3
[2024-02-29 16:25:40,552 INFO] validating...
[2024-02-29 16:25:45,241 INFO] model saved: saved_models/radformer/selfkd_v8_exp2/latest_model.pth
[2024-02-29 16:25:46,013 INFO] model saved: saved_models/radformer/selfkd_v8_exp2/model_best.pth
[2024-02-29 16:25:46,014 INFO] 225 iteration, USE_EMA: True, train/sup_loss: 0.77731, train/unsup_loss: 0.45570, train/total_loss: 1.23301, train/util_ratio: 0.62500, train/run_time: 0.95270, lr: 0.00600, train/prefecth_time: 0.02311, eval/loss: 0.91653, eval/top-1-acc: 0.80000, eval/balanced_acc: 0.51395, eval/precision: 0.79101, eval/recall: 0.51395, eval/F1: 0.55914, eval/spec: 0.44444, eval/sens: 0.98630, test/loss: 1.08444, test/top-1-acc: 0.38525, test/balanced_acc: 0.35488, test/precision: 0.26830, test/recall: 0.35488, test/F1: 0.28695, test/spec: 0.31250, test/sens: 0.73810 BEST_EVAL_ACC: 0.8000, at 225 iters BEST_TEST_ACC: 0.3852, at 225 iters
[2024-02-29 16:25:46,018 INFO] 

epoch 4
[2024-02-29 16:26:48,452 INFO] validating...
[2024-02-29 16:26:53,614 INFO] model saved: saved_models/radformer/selfkd_v8_exp2/latest_model.pth
[2024-02-29 16:26:53,616 INFO] 281 iteration, USE_EMA: True, train/sup_loss: 0.66778, train/unsup_loss: 0.46686, train/total_loss: 1.13464, train/util_ratio: 0.66071, train/run_time: 0.95495, lr: 0.00800, train/prefecth_time: 0.03387, eval/loss: 0.88321, eval/top-1-acc: 0.76000, eval/balanced_acc: 0.43531, eval/precision: 0.55991, eval/recall: 0.43531, eval/F1: 0.44839, eval/spec: 0.40741, eval/sens: 0.97260, test/loss: 1.07692, test/top-1-acc: 0.41803, test/balanced_acc: 0.37528, test/precision: 0.28384, test/recall: 0.37528, test/F1: 0.32099, test/spec: 0.48750, test/sens: 0.59524 BEST_EVAL_ACC: 0.8000, at 225 iters BEST_TEST_ACC: 0.3852, at 225 iters
[2024-02-29 16:26:53,619 INFO] 

epoch 5
[2024-02-29 16:27:56,717 INFO] validating...
[2024-02-29 16:28:01,877 INFO] model saved: saved_models/radformer/selfkd_v8_exp2/latest_model.pth
[2024-02-29 16:28:01,878 INFO] 337 iteration, USE_EMA: True, train/sup_loss: 0.51925, train/unsup_loss: 0.43422, train/total_loss: 0.95347, train/util_ratio: 0.66071, train/run_time: 0.95489, lr: 0.01000, train/prefecth_time: 0.03627, eval/loss: 0.81821, eval/top-1-acc: 0.79000, eval/balanced_acc: 0.45840, eval/precision: 0.45535, eval/recall: 0.45840, eval/F1: 0.45054, eval/spec: 0.44444, eval/sens: 0.98630, test/loss: 1.07151, test/top-1-acc: 0.43443, test/balanced_acc: 0.39057, test/precision: 0.45461, test/recall: 0.39057, test/F1: 0.34770, test/spec: 0.57500, test/sens: 0.54762 BEST_EVAL_ACC: 0.8000, at 225 iters BEST_TEST_ACC: 0.3852, at 225 iters
[2024-02-29 16:28:01,890 INFO] 

epoch 6
[2024-02-29 16:29:04,200 INFO] validating...
[2024-02-29 16:29:09,203 INFO] model saved: saved_models/radformer/selfkd_v8_exp2/latest_model.pth
[2024-02-29 16:29:09,991 INFO] model saved: saved_models/radformer/selfkd_v8_exp2/model_best.pth
[2024-02-29 16:29:09,993 INFO] 393 iteration, USE_EMA: True, train/sup_loss: 0.57253, train/unsup_loss: 0.37159, train/total_loss: 0.94412, train/util_ratio: 0.61607, train/run_time: 0.96844, lr: 0.01200, train/prefecth_time: 0.04093, eval/loss: 0.77296, eval/top-1-acc: 0.80000, eval/balanced_acc: 0.52790, eval/precision: 0.69510, eval/recall: 0.52790, eval/F1: 0.56624, eval/spec: 0.48148, eval/sens: 0.97260, test/loss: 1.06188, test/top-1-acc: 0.45082, test/balanced_acc: 0.39851, test/precision: 0.63148, test/recall: 0.39851, test/F1: 0.35179, test/spec: 0.72500, test/sens: 0.42857 BEST_EVAL_ACC: 0.8000, at 393 iters BEST_TEST_ACC: 0.4508, at 393 iters
[2024-02-29 16:29:10,001 INFO] 

epoch 7
[2024-02-29 16:30:12,534 INFO] validating...
[2024-02-29 16:30:17,656 INFO] model saved: saved_models/radformer/selfkd_v8_exp2/latest_model.pth
[2024-02-29 16:30:17,658 INFO] 449 iteration, USE_EMA: True, train/sup_loss: 0.38655, train/unsup_loss: 0.39012, train/total_loss: 0.77667, train/util_ratio: 0.65179, train/run_time: 0.95890, lr: 0.01400, train/prefecth_time: 0.03004, eval/loss: 0.73064, eval/top-1-acc: 0.81000, eval/balanced_acc: 0.52790, eval/precision: 0.59973, eval/recall: 0.52790, eval/F1: 0.54275, eval/spec: 0.59259, eval/sens: 0.97260, test/loss: 1.05636, test/top-1-acc: 0.43443, test/balanced_acc: 0.38830, test/precision: 0.40033, test/recall: 0.38830, test/F1: 0.34678, test/spec: 0.62500, test/sens: 0.50000 BEST_EVAL_ACC: 0.8000, at 393 iters BEST_TEST_ACC: 0.4508, at 393 iters
[2024-02-29 16:30:17,663 INFO] 

epoch 8
[2024-02-29 16:31:21,270 INFO] validating...
[2024-02-29 16:31:25,759 INFO] model saved: saved_models/radformer/selfkd_v8_exp2/latest_model.pth
[2024-02-29 16:31:26,538 INFO] model saved: saved_models/radformer/selfkd_v8_exp2/model_best.pth
[2024-02-29 16:31:26,539 INFO] 505 iteration, USE_EMA: True, train/sup_loss: 0.48453, train/unsup_loss: 0.36422, train/total_loss: 0.84875, train/util_ratio: 0.60714, train/run_time: 0.95693, lr: 0.01600, train/prefecth_time: 0.02473, eval/loss: 0.68745, eval/top-1-acc: 0.84000, eval/balanced_acc: 0.62050, eval/precision: 0.76440, eval/recall: 0.62050, eval/F1: 0.66323, eval/spec: 0.62963, eval/sens: 0.97260, test/loss: 1.04938, test/top-1-acc: 0.45902, test/balanced_acc: 0.41208, test/precision: 0.47172, test/recall: 0.41208, test/F1: 0.38501, test/spec: 0.75000, test/sens: 0.40476 BEST_EVAL_ACC: 0.8400, at 505 iters BEST_TEST_ACC: 0.4590, at 505 iters
[2024-02-29 16:31:26,543 INFO] 

epoch 9
[2024-02-29 16:32:29,555 INFO] validating...
[2024-02-29 16:32:34,318 INFO] model saved: saved_models/radformer/selfkd_v8_exp2/latest_model.pth
[2024-02-29 16:32:34,320 INFO] 561 iteration, USE_EMA: True, train/sup_loss: 0.45981, train/unsup_loss: 0.32885, train/total_loss: 0.78866, train/util_ratio: 0.62500, train/run_time: 0.96124, lr: 0.01800, train/prefecth_time: 0.04772, eval/loss: 0.65709, eval/top-1-acc: 0.83000, eval/balanced_acc: 0.53704, eval/precision: 0.65091, eval/recall: 0.53704, eval/F1: 0.55106, eval/spec: 0.66667, eval/sens: 1.00000, test/loss: 1.04282, test/top-1-acc: 0.48361, test/balanced_acc: 0.43475, test/precision: 0.51851, test/recall: 0.43475, test/F1: 0.40579, test/spec: 0.73750, test/sens: 0.45238 BEST_EVAL_ACC: 0.8400, at 505 iters BEST_TEST_ACC: 0.4590, at 505 iters
[2024-02-29 16:32:34,323 INFO] 

epoch 10
[2024-02-29 16:33:37,077 INFO] validating...
[2024-02-29 16:33:42,251 INFO] model saved: saved_models/radformer/selfkd_v8_exp2/latest_model.pth
[2024-02-29 16:33:42,252 INFO] 617 iteration, USE_EMA: True, train/sup_loss: 0.18448, train/unsup_loss: 0.33389, train/total_loss: 0.51837, train/util_ratio: 0.62500, train/run_time: 0.95191, lr: 0.02000, train/prefecth_time: 0.02971, eval/loss: 0.63596, eval/top-1-acc: 0.82000, eval/balanced_acc: 0.51395, eval/precision: 0.48148, eval/recall: 0.51395, eval/F1: 0.49687, eval/spec: 0.66667, eval/sens: 0.98630, test/loss: 1.03124, test/top-1-acc: 0.52459, test/balanced_acc: 0.45860, test/precision: 0.54774, test/recall: 0.45860, test/F1: 0.40132, test/spec: 0.88750, test/sens: 0.40476 BEST_EVAL_ACC: 0.8400, at 505 iters BEST_TEST_ACC: 0.4590, at 505 iters
[2024-02-29 16:33:42,255 INFO] 

epoch 11
[2024-02-29 16:34:45,486 INFO] validating...
[2024-02-29 16:34:50,075 INFO] model saved: saved_models/radformer/selfkd_v8_exp2/latest_model.pth
[2024-02-29 16:34:50,076 INFO] 673 iteration, USE_EMA: True, train/sup_loss: 0.31432, train/unsup_loss: 0.33882, train/total_loss: 0.65314, train/util_ratio: 0.60714, train/run_time: 0.95612, lr: 0.02000, train/prefecth_time: 0.03440, eval/loss: 0.60667, eval/top-1-acc: 0.85000, eval/balanced_acc: 0.62050, eval/precision: 0.83675, eval/recall: 0.62050, eval/F1: 0.64520, eval/spec: 0.74074, eval/sens: 0.97260, test/loss: 1.02620, test/top-1-acc: 0.53279, test/balanced_acc: 0.46822, test/precision: 0.60222, test/recall: 0.46822, test/F1: 0.41753, test/spec: 0.88750, test/sens: 0.38095 BEST_EVAL_ACC: 0.8400, at 505 iters BEST_TEST_ACC: 0.4590, at 505 iters
[2024-02-29 16:34:50,080 INFO] 

epoch 12
[2024-02-29 16:35:53,650 INFO] validating...
[2024-02-29 16:35:58,966 INFO] model saved: saved_models/radformer/selfkd_v8_exp2/latest_model.pth
[2024-02-29 16:35:58,969 INFO] 729 iteration, USE_EMA: True, train/sup_loss: 0.21321, train/unsup_loss: 0.29020, train/total_loss: 0.50340, train/util_ratio: 0.61607, train/run_time: 0.95563, lr: 0.01999, train/prefecth_time: 0.04784, eval/loss: 0.57165, eval/top-1-acc: 0.84000, eval/balanced_acc: 0.61593, eval/precision: 0.83922, eval/recall: 0.61593, eval/F1: 0.64445, eval/spec: 0.66667, eval/sens: 0.95890, test/loss: 1.01983, test/top-1-acc: 0.51639, test/balanced_acc: 0.45688, test/precision: 0.52083, test/recall: 0.45688, test/F1: 0.41260, test/spec: 0.82500, test/sens: 0.42857 BEST_EVAL_ACC: 0.8400, at 505 iters BEST_TEST_ACC: 0.4590, at 505 iters
[2024-02-29 16:35:58,975 INFO] 

epoch 13
[2024-02-29 16:37:03,055 INFO] validating...
[2024-02-29 16:37:08,609 INFO] model saved: saved_models/radformer/selfkd_v8_exp2/latest_model.pth
[2024-02-29 16:37:09,464 INFO] model saved: saved_models/radformer/selfkd_v8_exp2/model_best.pth
[2024-02-29 16:37:09,465 INFO] 785 iteration, USE_EMA: True, train/sup_loss: 0.20346, train/unsup_loss: 0.28588, train/total_loss: 0.48934, train/util_ratio: 0.64286, train/run_time: 0.96263, lr: 0.01998, train/prefecth_time: 0.03770, eval/loss: 0.57729, eval/top-1-acc: 0.85000, eval/balanced_acc: 0.64358, eval/precision: 0.79012, eval/recall: 0.64358, eval/F1: 0.69370, eval/spec: 0.62963, eval/sens: 0.98630, test/loss: 1.01436, test/top-1-acc: 0.51639, test/balanced_acc: 0.46251, test/precision: 0.57088, test/recall: 0.46251, test/F1: 0.43309, test/spec: 0.83750, test/sens: 0.38095 BEST_EVAL_ACC: 0.8500, at 785 iters BEST_TEST_ACC: 0.5164, at 785 iters
[2024-02-29 16:37:09,468 INFO] 

epoch 14
[2024-02-29 16:38:12,736 INFO] validating...
[2024-02-29 16:38:17,825 INFO] model saved: saved_models/radformer/selfkd_v8_exp2/latest_model.pth
[2024-02-29 16:38:18,771 INFO] model saved: saved_models/radformer/selfkd_v8_exp2/model_best.pth
[2024-02-29 16:38:18,772 INFO] 841 iteration, USE_EMA: True, train/sup_loss: 0.13523, train/unsup_loss: 0.24550, train/total_loss: 0.38072, train/util_ratio: 0.64286, train/run_time: 0.95948, lr: 0.01996, train/prefecth_time: 0.05086, eval/loss: 0.54394, eval/top-1-acc: 0.86000, eval/balanced_acc: 0.65753, eval/precision: 0.85513, eval/recall: 0.65753, eval/F1: 0.70029, eval/spec: 0.70370, eval/sens: 0.97260, test/loss: 1.00875, test/top-1-acc: 0.47541, test/balanced_acc: 0.42341, test/precision: 0.51311, test/recall: 0.42341, test/F1: 0.38970, test/spec: 0.78750, test/sens: 0.35714 BEST_EVAL_ACC: 0.8600, at 841 iters BEST_TEST_ACC: 0.4754, at 841 iters
[2024-02-29 16:38:18,776 INFO] 

epoch 15
[2024-02-29 16:39:22,531 INFO] validating...
[2024-02-29 16:39:28,074 INFO] model saved: saved_models/radformer/selfkd_v8_exp2/latest_model.pth
[2024-02-29 16:39:28,076 INFO] 897 iteration, USE_EMA: True, train/sup_loss: 0.14828, train/unsup_loss: 0.23856, train/total_loss: 0.38683, train/util_ratio: 0.66964, train/run_time: 0.95742, lr: 0.01994, train/prefecth_time: 0.03582, eval/loss: 0.54380, eval/top-1-acc: 0.86000, eval/balanced_acc: 0.59259, eval/precision: 0.85597, eval/recall: 0.59259, eval/F1: 0.60491, eval/spec: 0.70370, eval/sens: 1.00000, test/loss: 1.00128, test/top-1-acc: 0.50000, test/balanced_acc: 0.44496, test/precision: 0.57946, test/recall: 0.44496, test/F1: 0.40869, test/spec: 0.80000, test/sens: 0.38095 BEST_EVAL_ACC: 0.8600, at 841 iters BEST_TEST_ACC: 0.4754, at 841 iters
[2024-02-29 16:39:28,080 INFO] 

epoch 16
[2024-02-29 16:40:31,702 INFO] validating...
[2024-02-29 16:40:37,002 INFO] model saved: saved_models/radformer/selfkd_v8_exp2/latest_model.pth
[2024-02-29 16:40:37,004 INFO] 953 iteration, USE_EMA: True, train/sup_loss: 0.07987, train/unsup_loss: 0.20274, train/total_loss: 0.28261, train/util_ratio: 0.60714, train/run_time: 0.96604, lr: 0.01992, train/prefecth_time: 0.03659, eval/loss: 0.51462, eval/top-1-acc: 0.85000, eval/balanced_acc: 0.63902, eval/precision: 0.83662, eval/recall: 0.63902, eval/F1: 0.68177, eval/spec: 0.70370, eval/sens: 0.97260, test/loss: 0.99395, test/top-1-acc: 0.52459, test/balanced_acc: 0.47553, test/precision: 0.56250, test/recall: 0.47553, test/F1: 0.45628, test/spec: 0.82500, test/sens: 0.42857 BEST_EVAL_ACC: 0.8600, at 841 iters BEST_TEST_ACC: 0.4754, at 841 iters
[2024-02-29 16:40:37,007 INFO] 

epoch 17
[2024-02-29 16:41:39,940 INFO] validating...
[2024-02-29 16:41:44,822 INFO] model saved: saved_models/radformer/selfkd_v8_exp2/latest_model.pth
[2024-02-29 16:41:44,825 INFO] 1009 iteration, USE_EMA: True, train/sup_loss: 0.16431, train/unsup_loss: 0.18843, train/total_loss: 0.35274, train/util_ratio: 0.59821, train/run_time: 0.96280, lr: 0.01989, train/prefecth_time: 0.03622, eval/loss: 0.46491, eval/top-1-acc: 0.84000, eval/balanced_acc: 0.60198, eval/precision: 0.71862, eval/recall: 0.60198, eval/F1: 0.62278, eval/spec: 0.74074, eval/sens: 0.97260, test/loss: 0.98966, test/top-1-acc: 0.51639, test/balanced_acc: 0.48511, test/precision: 0.55556, test/recall: 0.48511, test/F1: 0.48588, test/spec: 0.72500, test/sens: 0.52381 BEST_EVAL_ACC: 0.8600, at 841 iters BEST_TEST_ACC: 0.4754, at 841 iters
[2024-02-29 16:41:44,829 INFO] 

epoch 18
[2024-02-29 16:42:48,037 INFO] validating...
[2024-02-29 16:42:53,365 INFO] model saved: saved_models/radformer/selfkd_v8_exp2/latest_model.pth
[2024-02-29 16:42:53,366 INFO] 1065 iteration, USE_EMA: True, train/sup_loss: 0.13670, train/unsup_loss: 0.22488, train/total_loss: 0.36158, train/util_ratio: 0.63393, train/run_time: 0.96416, lr: 0.01985, train/prefecth_time: 0.04568, eval/loss: 0.45024, eval/top-1-acc: 0.83000, eval/balanced_acc: 0.58803, eval/precision: 0.81297, eval/recall: 0.58803, eval/F1: 0.64103, eval/spec: 0.59259, eval/sens: 0.98630, test/loss: 0.98358, test/top-1-acc: 0.51639, test/balanced_acc: 0.48457, test/precision: 0.56581, test/recall: 0.48457, test/F1: 0.48073, test/spec: 0.66250, test/sens: 0.59524 BEST_EVAL_ACC: 0.8600, at 841 iters BEST_TEST_ACC: 0.4754, at 841 iters
[2024-02-29 16:42:53,370 INFO] 

epoch 19
[2024-02-29 16:43:56,588 INFO] validating...
[2024-02-29 16:44:01,388 INFO] model saved: saved_models/radformer/selfkd_v8_exp2/latest_model.pth
[2024-02-29 16:44:01,390 INFO] 1121 iteration, USE_EMA: True, train/sup_loss: 0.15897, train/unsup_loss: 0.19271, train/total_loss: 0.35168, train/util_ratio: 0.63393, train/run_time: 0.96109, lr: 0.01981, train/prefecth_time: 0.03450, eval/loss: 0.45274, eval/top-1-acc: 0.84000, eval/balanced_acc: 0.62050, eval/precision: 0.83385, eval/recall: 0.62050, eval/F1: 0.67010, eval/spec: 0.62963, eval/sens: 0.97260, test/loss: 0.97806, test/top-1-acc: 0.52459, test/balanced_acc: 0.49927, test/precision: 0.56693, test/recall: 0.49927, test/F1: 0.50271, test/spec: 0.68750, test/sens: 0.59524 BEST_EVAL_ACC: 0.8600, at 841 iters BEST_TEST_ACC: 0.4754, at 841 iters
[2024-02-29 16:44:01,393 INFO] 

epoch 20
[2024-02-29 16:45:03,823 INFO] validating...
[2024-02-29 16:45:08,507 INFO] model saved: saved_models/radformer/selfkd_v8_exp2/latest_model.pth
[2024-02-29 16:45:08,509 INFO] 1177 iteration, USE_EMA: True, train/sup_loss: 0.12144, train/unsup_loss: 0.17265, train/total_loss: 0.29409, train/util_ratio: 0.61607, train/run_time: 0.95385, lr: 0.01977, train/prefecth_time: 0.03053, eval/loss: 0.43279, eval/top-1-acc: 0.83000, eval/balanced_acc: 0.61593, eval/precision: 0.74144, eval/recall: 0.61593, eval/F1: 0.65134, eval/spec: 0.66667, eval/sens: 0.95890, test/loss: 0.97062, test/top-1-acc: 0.52459, test/balanced_acc: 0.49645, test/precision: 0.59957, test/recall: 0.49645, test/F1: 0.49755, test/spec: 0.65000, test/sens: 0.61905 BEST_EVAL_ACC: 0.8600, at 841 iters BEST_TEST_ACC: 0.4754, at 841 iters
[2024-02-29 16:45:08,512 INFO] 

epoch 21
[2024-02-29 16:46:11,954 INFO] validating...
[2024-02-29 16:46:17,214 INFO] model saved: saved_models/radformer/selfkd_v8_exp2/latest_model.pth
[2024-02-29 16:46:17,216 INFO] 1233 iteration, USE_EMA: True, train/sup_loss: 0.21053, train/unsup_loss: 0.17919, train/total_loss: 0.38972, train/util_ratio: 0.65179, train/run_time: 0.96747, lr: 0.01972, train/prefecth_time: 0.03810, eval/loss: 0.39936, eval/top-1-acc: 0.84000, eval/balanced_acc: 0.62050, eval/precision: 0.83385, eval/recall: 0.62050, eval/F1: 0.67010, eval/spec: 0.62963, eval/sens: 0.97260, test/loss: 0.96726, test/top-1-acc: 0.52459, test/balanced_acc: 0.49532, test/precision: 0.59915, test/recall: 0.49532, test/F1: 0.49699, test/spec: 0.66250, test/sens: 0.59524 BEST_EVAL_ACC: 0.8600, at 841 iters BEST_TEST_ACC: 0.4754, at 841 iters
[2024-02-29 16:46:17,221 INFO] 

epoch 22
[2024-02-29 16:47:21,292 INFO] validating...
[2024-02-29 16:47:26,140 INFO] model saved: saved_models/radformer/selfkd_v8_exp2/latest_model.pth
[2024-02-29 16:47:26,923 INFO] model saved: saved_models/radformer/selfkd_v8_exp2/model_best.pth
[2024-02-29 16:47:26,926 INFO] 1289 iteration, USE_EMA: True, train/sup_loss: 0.17978, train/unsup_loss: 0.14083, train/total_loss: 0.32061, train/util_ratio: 0.58929, train/run_time: 0.97035, lr: 0.01967, train/prefecth_time: 0.03765, eval/loss: 0.38185, eval/top-1-acc: 0.85000, eval/balanced_acc: 0.65753, eval/precision: 0.84774, eval/recall: 0.65753, eval/F1: 0.71451, eval/spec: 0.62963, eval/sens: 0.97260, test/loss: 0.96114, test/top-1-acc: 0.55738, test/balanced_acc: 0.54060, test/precision: 0.61549, test/recall: 0.54060, test/F1: 0.55109, test/spec: 0.67500, test/sens: 0.64286 BEST_EVAL_ACC: 0.8500, at 1289 iters BEST_TEST_ACC: 0.5574, at 1289 iters
[2024-02-29 16:47:26,930 INFO] 

epoch 23
[2024-02-29 16:48:30,938 INFO] validating...
[2024-02-29 16:48:35,947 INFO] model saved: saved_models/radformer/selfkd_v8_exp2/latest_model.pth
[2024-02-29 16:48:36,839 INFO] model saved: saved_models/radformer/selfkd_v8_exp2/model_best.pth
[2024-02-29 16:48:36,841 INFO] 1345 iteration, USE_EMA: True, train/sup_loss: 0.17715, train/unsup_loss: 0.14344, train/total_loss: 0.32059, train/util_ratio: 0.60714, train/run_time: 0.95760, lr: 0.01961, train/prefecth_time: 0.03323, eval/loss: 0.39007, eval/top-1-acc: 0.89000, eval/balanced_acc: 0.75013, eval/precision: 0.90374, eval/recall: 0.75013, eval/F1: 0.80440, eval/spec: 0.70370, eval/sens: 0.97260, test/loss: 0.95763, test/top-1-acc: 0.54098, test/balanced_acc: 0.52981, test/precision: 0.60440, test/recall: 0.52981, test/F1: 0.54317, test/spec: 0.65000, test/sens: 0.61905 BEST_EVAL_ACC: 0.8900, at 1345 iters BEST_TEST_ACC: 0.5410, at 1345 iters
[2024-02-29 16:48:36,846 INFO] 

epoch 24
[2024-02-29 16:49:40,439 INFO] validating...
[2024-02-29 16:49:45,325 INFO] model saved: saved_models/radformer/selfkd_v8_exp2/latest_model.pth
[2024-02-29 16:49:45,329 INFO] 1401 iteration, USE_EMA: True, train/sup_loss: 0.11695, train/unsup_loss: 0.15977, train/total_loss: 0.27672, train/util_ratio: 0.67857, train/run_time: 0.95482, lr: 0.01954, train/prefecth_time: 0.03972, eval/loss: 0.36688, eval/top-1-acc: 0.89000, eval/balanced_acc: 0.75013, eval/precision: 0.89165, eval/recall: 0.75013, eval/F1: 0.79918, eval/spec: 0.74074, eval/sens: 0.97260, test/loss: 0.95319, test/top-1-acc: 0.54098, test/balanced_acc: 0.52926, test/precision: 0.59028, test/recall: 0.52926, test/F1: 0.53537, test/spec: 0.63750, test/sens: 0.69048 BEST_EVAL_ACC: 0.8900, at 1345 iters BEST_TEST_ACC: 0.5410, at 1345 iters
[2024-02-29 16:49:45,333 INFO] 

epoch 25
[2024-02-29 16:50:48,100 INFO] validating...
[2024-02-29 16:50:52,490 INFO] model saved: saved_models/radformer/selfkd_v8_exp2/latest_model.pth
[2024-02-29 16:50:52,493 INFO] 1457 iteration, USE_EMA: True, train/sup_loss: 0.10607, train/unsup_loss: 0.14809, train/total_loss: 0.25416, train/util_ratio: 0.62500, train/run_time: 0.96318, lr: 0.01948, train/prefecth_time: 0.03755, eval/loss: 0.35331, eval/top-1-acc: 0.89000, eval/balanced_acc: 0.70370, eval/precision: 0.90041, eval/recall: 0.70370, eval/F1: 0.76357, eval/spec: 0.70370, eval/sens: 1.00000, test/loss: 0.94860, test/top-1-acc: 0.56557, test/balanced_acc: 0.54740, test/precision: 0.63762, test/recall: 0.54740, test/F1: 0.56001, test/spec: 0.70000, test/sens: 0.64286 BEST_EVAL_ACC: 0.8900, at 1345 iters BEST_TEST_ACC: 0.5410, at 1345 iters
[2024-02-29 16:50:52,496 INFO] 

epoch 26
[2024-02-29 16:51:55,104 INFO] validating...
[2024-02-29 16:52:00,040 INFO] model saved: saved_models/radformer/selfkd_v8_exp2/latest_model.pth
[2024-02-29 16:52:00,041 INFO] 1513 iteration, USE_EMA: True, train/sup_loss: 0.10682, train/unsup_loss: 0.12295, train/total_loss: 0.22977, train/util_ratio: 0.67857, train/run_time: 0.95586, lr: 0.01941, train/prefecth_time: 0.03732, eval/loss: 0.33613, eval/top-1-acc: 0.88000, eval/balanced_acc: 0.73161, eval/precision: 0.86291, eval/recall: 0.73161, eval/F1: 0.77587, eval/spec: 0.77778, eval/sens: 0.97260, test/loss: 0.93977, test/top-1-acc: 0.55738, test/balanced_acc: 0.54455, test/precision: 0.61675, test/recall: 0.54455, test/F1: 0.55712, test/spec: 0.68750, test/sens: 0.64286 BEST_EVAL_ACC: 0.8900, at 1345 iters BEST_TEST_ACC: 0.5410, at 1345 iters
[2024-02-29 16:52:00,044 INFO] 

epoch 27
[2024-02-29 16:53:02,860 INFO] validating...
[2024-02-29 16:53:07,879 INFO] model saved: saved_models/radformer/selfkd_v8_exp2/latest_model.pth
[2024-02-29 16:53:07,881 INFO] 1569 iteration, USE_EMA: True, train/sup_loss: 0.10449, train/unsup_loss: 0.11863, train/total_loss: 0.22312, train/util_ratio: 0.62500, train/run_time: 0.96146, lr: 0.01933, train/prefecth_time: 0.04344, eval/loss: 0.37869, eval/top-1-acc: 0.87000, eval/balanced_acc: 0.72248, eval/precision: 0.81491, eval/recall: 0.72248, eval/F1: 0.75145, eval/spec: 0.74074, eval/sens: 0.94521, test/loss: 0.93475, test/top-1-acc: 0.55738, test/balanced_acc: 0.54341, test/precision: 0.60505, test/recall: 0.54341, test/F1: 0.55554, test/spec: 0.72500, test/sens: 0.61905 BEST_EVAL_ACC: 0.8900, at 1345 iters BEST_TEST_ACC: 0.5410, at 1345 iters
[2024-02-29 16:53:07,887 INFO] 

epoch 28
[2024-02-29 16:54:11,081 INFO] validating...
[2024-02-29 16:54:15,660 INFO] model saved: saved_models/radformer/selfkd_v8_exp2/latest_model.pth
[2024-02-29 16:54:15,662 INFO] 1625 iteration, USE_EMA: True, train/sup_loss: 0.07660, train/unsup_loss: 0.12710, train/total_loss: 0.20370, train/util_ratio: 0.66071, train/run_time: 0.96066, lr: 0.01925, train/prefecth_time: 0.04474, eval/loss: 0.32271, eval/top-1-acc: 0.88000, eval/balanced_acc: 0.72704, eval/precision: 0.87368, eval/recall: 0.72704, eval/F1: 0.76394, eval/spec: 0.77778, eval/sens: 0.95890, test/loss: 0.93335, test/top-1-acc: 0.55738, test/balanced_acc: 0.54228, test/precision: 0.61763, test/recall: 0.54228, test/F1: 0.55685, test/spec: 0.72500, test/sens: 0.59524 BEST_EVAL_ACC: 0.8900, at 1345 iters BEST_TEST_ACC: 0.5410, at 1345 iters
[2024-02-29 16:54:15,665 INFO] 

epoch 29
[2024-02-29 16:55:18,140 INFO] validating...
[2024-02-29 16:55:22,938 INFO] model saved: saved_models/radformer/selfkd_v8_exp2/latest_model.pth
[2024-02-29 16:55:22,940 INFO] 1681 iteration, USE_EMA: True, train/sup_loss: 0.07832, train/unsup_loss: 0.11590, train/total_loss: 0.19421, train/util_ratio: 0.63393, train/run_time: 0.95741, lr: 0.01916, train/prefecth_time: 0.02169, eval/loss: 0.36304, eval/top-1-acc: 0.86000, eval/balanced_acc: 0.69457, eval/precision: 0.85139, eval/recall: 0.69457, eval/F1: 0.74948, eval/spec: 0.66667, eval/sens: 0.97260, test/loss: 0.93243, test/top-1-acc: 0.57377, test/balanced_acc: 0.55702, test/precision: 0.63037, test/recall: 0.55702, test/F1: 0.57051, test/spec: 0.73750, test/sens: 0.61905 BEST_EVAL_ACC: 0.8900, at 1345 iters BEST_TEST_ACC: 0.5410, at 1345 iters
[2024-02-29 16:55:22,944 INFO] 

epoch 30
[2024-02-29 16:56:25,799 INFO] validating...
[2024-02-29 16:56:30,946 INFO] model saved: saved_models/radformer/selfkd_v8_exp2/latest_model.pth
[2024-02-29 16:56:30,947 INFO] 1737 iteration, USE_EMA: True, train/sup_loss: 0.11570, train/unsup_loss: 0.09579, train/total_lo--- Logging error ---
Traceback (most recent call last):
  File "/home/deepankar/scratch/miniconda3/envs/msa_medical/lib/python3.8/logging/__init__.py", line 1089, in emit
    self.flush()
  File "/home/deepankar/scratch/miniconda3/envs/msa_medical/lib/python3.8/logging/__init__.py", line 1069, in flush
    self.stream.flush()
OSError: [Errno 28] No space left on device
Call stack:
  File "/home/deepankar/scratch/miniconda3/envs/msa_medical/lib/python3.8/threading.py", line 890, in _bootstrap
    self._bootstrap_inner()
  File "/home/deepankar/scratch/miniconda3/envs/msa_medical/lib/python3.8/threading.py", line 932, in _bootstrap_inner
    self.run()
  File "/home/deepankar/scratch/miniconda3/envs/msa_medical/lib/python3.8/site-packages/wandb/sdk/internal/internal_util.py", line 49, in run
    self._run()
  File "/home/deepankar/scratch/miniconda3/envs/msa_medical/lib/python3.8/site-packages/wandb/sdk/internal/internal_util.py", line 101, in _run
    self._finish()
  File "/home/deepankar/scratch/miniconda3/envs/msa_medical/lib/python3.8/site-packages/wandb/sdk/internal/internal.py", line 331, in _finish
    self._sm.finish()
  File "/home/deepankar/scratch/miniconda3/envs/msa_medical/lib/python3.8/site-packages/wandb/sdk/internal/sender.py", line 1572, in finish
    logger.info("shutting down sender")
Message: 'shutting down sender'
Arguments: ()
--- Logging error ---
Traceback (most recent call last):
  File "/home/deepankar/scratch/miniconda3/envs/msa_medical/lib/python3.8/logging/__init__.py", line 1089, in emit
    self.flush()
  File "/home/deepankar/scratch/miniconda3/envs/msa_medical/lib/python3.8/logging/__init__.py", line 1069, in flush
    self.stream.flush()
OSError: [Errno 28] No space left on device
Call stack:
  File "/home/deepankar/scratch/miniconda3/envs/msa_medical/lib/python3.8/threading.py", line 890, in _bootstrap
    self._bootstrap_inner()
  File "/home/deepankar/scratch/miniconda3/envs/msa_medical/lib/python3.8/threading.py", line 932, in _bootstrap_inner
    self.run()
  File "/home/deepankar/scratch/miniconda3/envs/msa_medical/lib/python3.8/site-packages/wandb/sdk/service/streams.py", line 48, in run
    self._target(**self._kwargs)
  File "/home/deepankar/scratch/miniconda3/envs/msa_medical/lib/python3.8/site-packages/wandb/sdk/internal/internal.py", line 174, in wandb_internal
    logger.error(f"Thread {thread.name}:", exc_info=exc_info)
Message: 'Thread SenderThread:'
Arguments: ()
Thread SenderThread:
Traceback (most recent call last):
  File "/home/deepankar/scratch/miniconda3/envs/msa_medical/lib/python3.8/site-packages/wandb/sdk/internal/internal_util.py", line 49, in run
    self._run()
  File "/home/deepankar/scratch/miniconda3/envs/msa_medical/lib/python3.8/site-packages/wandb/sdk/internal/internal_util.py", line 101, in _run
    self._finish()
  File "/home/deepankar/scratch/miniconda3/envs/msa_medical/lib/python3.8/site-packages/wandb/sdk/internal/internal.py", line 331, in _finish
    self._sm.finish()
  File "/home/deepankar/scratch/miniconda3/envs/msa_medical/lib/python3.8/site-packages/wandb/sdk/internal/sender.py", line 1575, in finish
    self._output_raw_finish()
  File "/home/deepankar/scratch/miniconda3/envs/msa_medical/lib/python3.8/site-packages/wandb/sdk/internal/sender.py", line 1211, in _output_raw_finish
    self._output_raw_flush(stream)
  File "/home/deepankar/scratch/miniconda3/envs/msa_medical/lib/python3.8/site-packages/wandb/sdk/internal/sender.py", line 1258, in _output_raw_flush
    self._output_raw_file.write(data.encode("utf-8"))
  File "/home/deepankar/scratch/miniconda3/envs/msa_medical/lib/python3.8/site-packages/wandb/sdk/lib/filesystem.py", line 128, in write
    super().write(b"\n".join(ret) + b"\n")
  File "/home/deepankar/scratch/miniconda3/envs/msa_medical/lib/python3.8/site-packages/wandb/sdk/lib/filesystem.py", line 95, in write
    self.f.flush()
OSError: [Errno 28] No space left on device
wandb: ERROR Internal wandb error: file data was not synced
Exception in threading.excepthook:
--- Logging error ---
Traceback (most recent call last):
  File "/home/deepankar/scratch/miniconda3/envs/msa_medical/lib/python3.8/logging/__init__.py", line 1089, in emit
    self.flush()
  File "/home/deepankar/scratch/miniconda3/envs/msa_medical/lib/python3.8/logging/__init__.py", line 1069, in flush
    self.stream.flush()
OSError: [Errno 28] No space left on device
Call stack:
  File "/home/deepankar/scratch/miniconda3/envs/msa_medical/lib/python3.8/threading.py", line 890, in _bootstrap
    self._bootstrap_inner()
  File "/home/deepankar/scratch/miniconda3/envs/msa_medical/lib/python3.8/threading.py", line 932, in _bootstrap_inner
    self.run()
  File "/home/deepankar/scratch/miniconda3/envs/msa_medical/lib/python3.8/site-packages/wandb/vendor/watchdog_0_9_0/wandb_watchdog/observers/api.py", line 199, in run
    self.dispatch_events(self.event_queue, self.timeout)
  File "/home/deepankar/scratch/miniconda3/envs/msa_medical/lib/python3.8/site-packages/wandb/vendor/watchdog_0_9_0/wandb_watchdog/observers/api.py", line 368, in dispatch_events
    handler.dispatch(event)
  File "/home/deepankar/scratch/miniconda3/envs/msa_medical/lib/python3.8/site-packages/wandb/vendor/watchdog_0_9_0/wandb_watchdog/events.py", line 454, in dispatch
    _method_map[event_type](event)
  File "/home/deepankar/scratch/miniconda3/envs/msa_medical/lib/python3.8/site-packages/wandb/filesync/dir_watcher.py", line 288, in _on_file_modified
    logger.info(f"file/dir modified: { event.src_path}")
Message: 'file/dir modified: saved_models/radformer/wandb/selfkd_v8_exp2/wandb/run-20240229_153310-e7mxdf4s/files/output.log'
Arguments: ()
--- Logging error ---
Traceback (most recent call last):
  File "/home/deepankar/scratch/miniconda3/envs/msa_medical/lib/python3.8/site-packages/urllib3/connectionpool.py", line 712, in urlopen
    self._prepare_proxy(conn)
  File "/home/deepankar/scratch/miniconda3/envs/msa_medical/lib/python3.8/site-packages/urllib3/connectionpool.py", line 1012, in _prepare_proxy
    conn.connect()
  File "/home/deepankar/scratch/miniconda3/envs/msa_medical/lib/python3.8/site-packages/urllib3/connection.py", line 374, in connect
    self._tunnel()
  File "/home/deepankar/scratch/miniconda3/envs/msa_medical/lib/python3.8/http/client.py", line 905, in _tunnel
    raise OSError("Tunnel connection failed: %d %s" % (code,
OSError: Tunnel connection failed: 302 Moved Temporarily

During handling of the above exception, another exception occurred:

Traceback (most recent call last):
  File "/home/deepankar/scratch/miniconda3/envs/msa_medical/lib/python3.8/site-packages/requests/adapters.py", line 440, in send
    resp = conn.urlopen(
  File "/home/deepankar/scratch/miniconda3/envs/msa_medical/lib/python3.8/site-packages/urllib3/connectionpool.py", line 799, in urlopen
    retries = retries.increment(
  File "/home/deepankar/scratch/miniconda3/envs/msa_medical/lib/python3.8/site-packages/urllib3/util/retry.py", line 592, in increment
    raise MaxRetryError(_pool, url, error or ResponseError(cause))
urllib3.exceptions.MaxRetryError: HTTPSConnectionPool(host='api.wandb.ai', port=443): Max retries exceeded with url: /files/satwikdpshrit/radformer/e7mxdf4s/file_stream (Caused by ProxyError('Cannot connect to proxy.', OSError('Tunnel connection failed: 302 Moved Temporarily')))

During handling of the above exception, another exception occurred:

Traceback (most recent call last):
  File "/home/deepankar/scratch/miniconda3/envs/msa_medical/lib/python3.8/site-packages/wandb/sdk/internal/file_stream.py", line 630, in request_with_retry
    response: requests.Response = func(*args, **kwargs)
  File "/home/deepankar/scratch/miniconda3/envs/msa_medical/lib/python3.8/site-packages/requests/sessions.py", line 577, in post
    return self.request('POST', url, data=data, json=json, **kwargs)
  File "/home/deepankar/scratch/miniconda3/envs/msa_medical/lib/python3.8/site-packages/requests/sessions.py", line 529, in request
    resp = self.send(prep, **send_kwargs)
  File "/home/deepankar/scratch/miniconda3/envs/msa_medical/lib/python3.8/site-packages/requests/sessions.py", line 645, in send
    r = adapter.send(request, **kwargs)
  File "/home/deepankar/scratch/miniconda3/envs/msa_medical/lib/python3.8/site-packages/requests/adapters.py", line 513, in send
    raise ProxyError(e, request=request)
requests.exceptions.ProxyError: HTTPSConnectionPool(host='api.wandb.ai', port=443): Max retries exceeded with url: /files/satwikdpshrit/radformer/e7mxdf4s/file_stream (Caused by ProxyError('Cannot connect to proxy.', OSError('Tunnel connection failed: 302 Moved Temporarily')))

During handling of the above exception, another exception occurred:

Traceback (most recent call last):
  File "/home/deepankar/scratch/miniconda3/envs/msa_medical/lib/python3.8/logging/__init__.py", line 1089, in emit
    self.flush()
  File "/home/deepankar/scratch/miniconda3/envs/msa_medical/lib/python3.8/logging/__init__.py", line 1069, in flush
    self.stream.flush()
OSError: [Errno 28] No space left on device
Call stack:
  File "/home/deepankar/scratch/miniconda3/envs/msa_medical/lib/python3.8/threading.py", line 890, in _bootstrap
    self._bootstrap_inner()
  File "/home/deepankar/scratch/miniconda3/envs/msa_medical/lib/python3.8/threading.py", line 932, in _bootstrap_inner
    self.run()
  File "/home/deepankar/scratch/miniconda3/envs/msa_medical/lib/python3.8/threading.py", line 870, in run
    self._target(*self._args, **self._kwargs)
  File "/home/deepankar/scratch/miniconda3/envs/msa_medical/lib/python3.8/site-packages/wandb/sdk/internal/file_stream.py", line 490, in _thread_except_body
    self._thread_body()
  File "/home/deepankar/scratch/miniconda3/envs/msa_medical/lib/python3.8/site-packages/wandb/sdk/internal/file_stream.py", line 461, in _thread_body
    request_with_retry(
  File "/home/deepankar/scratch/miniconda3/envs/msa_medical/lib/python3.8/site-packages/wandb/sdk/internal/file_stream.py", line 668, in request_with_retry
    logger.warning(
Message: 'requests_with_retry encountered retryable exception: %s. func: %s, args: %s, kwargs: %s'
Arguments: (ProxyError(MaxRetryError("HTTPSConnectionPool(host='api.wandb.ai', port=443): Max retries exceeded with url: /files/satwikdpshrit/radformer/e7mxdf4s/file_stream (Caused by ProxyError('Cannot connect to proxy.', OSError('Tunnel connection failed: 302 Moved Temporarily')))")), functools.partial(<bound method Session.post of <requests.sessions.Session object at 0x7f3794732190>>, timeout=180.0), ('https://api.wandb.ai/files/satwikdpshrit/radformer/e7mxdf4s/file_stream',), {'json': {'complete': False, 'failed': False, 'dropped': 0, 'uploaded': []}})
--- Logging error ---
Traceback (most recent call last):
  File "/home/deepankar/scratch/miniconda3/envs/msa_medical/lib/python3.8/site-packages/urllib3/connectionpool.py", line 712, in urlopen
    self._prepare_proxy(conn)
  File "/home/deepankar/scratch/miniconda3/envs/msa_medical/lib/python3.8/site-packages/urllib3/connectionpool.py", line 1012, in _prepare_proxy
    conn.connect()
  File "/home/deepankar/scratch/miniconda3/envs/msa_medical/lib/python3.8/site-packages/urllib3/connection.py", line 374, in connect
    self._tunnel()
  File "/home/deepankar/scratch/miniconda3/envs/msa_medical/lib/python3.8/http/client.py", line 905, in _tunnel
    raise OSError("Tunnel connection failed: %d %s" % (code,
OSError: Tunnel connection failed: 302 Moved Temporarily

During handling of the above exception, another exception occurred:

Traceback (most recent call last):
  File "/home/deepankar/scratch/miniconda3/envs/msa_medical/lib/python3.8/site-packages/requests/adapters.py", line 440, in send
    resp = conn.urlopen(
  File "/home/deepankar/scratch/miniconda3/envs/msa_medical/lib/python3.8/site-packages/urllib3/connectionpool.py", line 799, in urlopen
    retries = retries.increment(
  File "/home/deepankar/scratch/miniconda3/envs/msa_medical/lib/python3.8/site-packages/urllib3/util/retry.py", line 592, in increment
    raise MaxRetryError(_pool, url, error or ResponseError(cause))
urllib3.exceptions.MaxRetryError: HTTPSConnectionPool(host='api.wandb.ai', port=443): Max retries exceeded with url: /files/satwikdpshrit/radformer/e7mxdf4s/file_stream (Caused by ProxyError('Cannot connect to proxy.', OSError('Tunnel connection failed: 302 Moved Temporarily')))

During handling of the above exception, another exception occurred:

Traceback (most recent call last):
  File "/home/deepankar/scratch/miniconda3/envs/msa_medical/lib/python3.8/site-packages/wandb/sdk/internal/file_stream.py", line 630, in request_with_retry
    response: requests.Response = func(*args, **kwargs)
  File "/home/deepankar/scratch/miniconda3/envs/msa_medical/lib/python3.8/site-packages/requests/sessions.py", line 577, in post
    return self.request('POST', url, data=data, json=json, **kwargs)
  File "/home/deepankar/scratch/miniconda3/envs/msa_medical/lib/python3.8/site-packages/requests/sessions.py", line 529, in request
    resp = self.send(prep, **send_kwargs)
  File "/home/deepankar/scratch/miniconda3/envs/msa_medical/lib/python3.8/site-packages/requests/sessions.py", line 645, in send
    r = adapter.send(request, **kwargs)
  File "/home/deepankar/scratch/miniconda3/envs/msa_medical/lib/python3.8/site-packages/requests/adapters.py", line 513, in send
    raise ProxyError(e, request=request)
requests.exceptions.ProxyError: HTTPSConnectionPool(host='api.wandb.ai', port=443): Max retries exceeded with url: /files/satwikdpshrit/radformer/e7mxdf4s/file_stream (Caused by ProxyError('Cannot connect to proxy.', OSError('Tunnel connection failed: 302 Moved Temporarily')))

During handling of the above exception, another exception occurred:

Traceback (most recent call last):
  File "/home/deepankar/scratch/miniconda3/envs/msa_medical/lib/python3.8/logging/__init__.py", line 1089, in emit
    self.flush()
  File "/home/deepankar/scratch/miniconda3/envs/msa_medical/lib/python3.8/logging/__init__.py", line 1069, in flush
    self.stream.flush()
OSError: [Errno 28] No space left on device
Call stack:
  File "/home/deepankar/scratch/miniconda3/envs/msa_medical/lib/python3.8/threading.py", line 890, in _bootstrap
    self._bootstrap_inner()
  File "/home/deepankar/scratch/miniconda3/envs/msa_medical/lib/python3.8/threading.py", line 932, in _bootstrap_inner
    self.run()
  File "/home/deepankar/scratch/miniconda3/envs/msa_medical/lib/python3.8/threading.py", line 870, in run
    self._target(*self._args, **self._kwargs)
  File "/home/deepankar/scratch/miniconda3/envs/msa_medical/lib/python3.8/site-packages/wandb/sdk/internal/file_stream.py", line 490, in _thread_except_body
    self._thread_body()
  File "/home/deepankar/scratch/miniconda3/envs/msa_medical/lib/python3.8/site-packages/wandb/sdk/internal/file_stream.py", line 461, in _thread_body
    request_with_retry(
  File "/home/deepankar/scratch/miniconda3/envs/msa_medical/lib/python3.8/site-packages/wandb/sdk/internal/file_stream.py", line 668, in request_with_retry
    logger.warning(
Message: 'requests_with_retry encountered retryable exception: %s. func: %s, args: %s, kwargs: %s'
Arguments: (ProxyError(MaxRetryError("HTTPSConnectionPool(host='api.wandb.ai', port=443): Max retries exceeded with url: /files/satwikdpshrit/radformer/e7mxdf4s/file_stream (Caused by ProxyError('Cannot connect to proxy.', OSError('Tunnel connection failed: 302 Moved Temporarily')))")), functools.partial(<bound method Session.post of <requests.sessions.Session object at 0x7f3794732190>>, timeout=180.0), ('https://api.wandb.ai/files/satwikdpshrit/radformer/e7mxdf4s/file_stream',), {'json': {'complete': False, 'failed': False, 'dropped': 0, 'uploaded': []}})
--- Logging error ---
Traceback (most recent call last):
  File "/home/deepankar/scratch/miniconda3/envs/msa_medical/lib/python3.8/site-packages/urllib3/connectionpool.py", line 712, in urlopen
    self._prepare_proxy(conn)
  File "/home/deepankar/scratch/miniconda3/envs/msa_medical/lib/python3.8/site-packages/urllib3/connectionpool.py", line 1012, in _prepare_proxy
    conn.connect()
  File "/home/deepankar/scratch/miniconda3/envs/msa_medical/lib/python3.8/site-packages/urllib3/connection.py", line 374, in connect
    self._tunnel()
  File "/home/deepankar/scratch/miniconda3/envs/msa_medical/lib/python3.8/http/client.py", line 905, in _tunnel
    raise OSError("Tunnel connection failed: %d %s" % (code,
OSError: Tunnel connection failed: 302 Moved Temporarily

During handling of the above exception, another exception occurred:

Traceback (most recent call last):
  File "/home/deepankar/scratch/miniconda3/envs/msa_medical/lib/python3.8/site-packages/requests/adapters.py", line 440, in send
    resp = conn.urlopen(
  File "/home/deepankar/scratch/miniconda3/envs/msa_medical/lib/python3.8/site-packages/urllib3/connectionpool.py", line 799, in urlopen
    retries = retries.increment(
  File "/home/deepankar/scratch/miniconda3/envs/msa_medical/lib/python3.8/site-packages/urllib3/util/retry.py", line 592, in increment
    raise MaxRetryError(_pool, url, error or ResponseError(cause))
urllib3.exceptions.MaxRetryError: HTTPSConnectionPool(host='api.wandb.ai', port=443): Max retries exceeded with url: /files/satwikdpshrit/radformer/e7mxdf4s/file_stream (Caused by ProxyError('Cannot connect to proxy.', OSError('Tunnel connection failed: 302 Moved Temporarily')))

During handling of the above exception, another exception occurred:

Traceback (most recent call last):
  File "/home/deepankar/scratch/miniconda3/envs/msa_medical/lib/python3.8/site-packages/wandb/sdk/internal/file_stream.py", line 630, in request_with_retry
    response: requests.Response = func(*args, **kwargs)
  File "/home/deepankar/scratch/miniconda3/envs/msa_medical/lib/python3.8/site-packages/requests/sessions.py", line 577, in post
    return self.request('POST', url, data=data, json=json, **kwargs)
  File "/home/deepankar/scratch/miniconda3/envs/msa_medical/lib/python3.8/site-packages/requests/sessions.py", line 529, in request
    resp = self.send(prep, **send_kwargs)
  File "/home/deepankar/scratch/miniconda3/envs/msa_medical/lib/python3.8/site-packages/requests/sessions.py", line 645, in send
    r = adapter.send(request, **kwargs)
  File "/home/deepankar/scratch/miniconda3/envs/msa_medical/lib/python3.8/site-packages/requests/adapters.py", line 513, in send
    raise ProxyError(e, request=request)
requests.exceptions.ProxyError: HTTPSConnectionPool(host='api.wandb.ai', port=443): Max retries exceeded with url: /files/satwikdpshrit/radformer/e7mxdf4s/file_stream (Caused by ProxyError('Cannot connect to proxy.', OSError('Tunnel connection failed: 302 Moved Temporarily')))

During handling of the above exception, another exception occurred:

Traceback (most recent call last):
  File "/home/deepankar/scratch/miniconda3/envs/msa_medical/lib/python3.8/logging/__init__.py", line 1089, in emit
    self.flush()
  File "/home/deepankar/scratch/miniconda3/envs/msa_medical/lib/python3.8/logging/__init__.py", line 1069, in flush
    self.stream.flush()
OSError: [Errno 28] No space left on device
Call stack:
  File "/home/deepankar/scratch/miniconda3/envs/msa_medical/lib/python3.8/threading.py", line 890, in _bootstrap
    self._bootstrap_inner()
  File "/home/deepankar/scratch/miniconda3/envs/msa_medical/lib/python3.8/threading.py", line 932, in _bootstrap_inner
    self.run()
  File "/home/deepankar/scratch/miniconda3/envs/msa_medical/lib/python3.8/threading.py", line 870, in run
    self._target(*self._args, **self._kwargs)
  File "/home/deepankar/scratch/miniconda3/envs/msa_medical/lib/python3.8/site-packages/wandb/sdk/internal/file_stream.py", line 490, in _thread_except_body
    self._thread_body()
  File "/home/deepankar/scratch/miniconda3/envs/msa_medical/lib/python3.8/site-packages/wandb/sdk/internal/file_stream.py", line 461, in _thread_body
    request_with_retry(
  File "/home/deepankar/scratch/miniconda3/envs/msa_medical/lib/python3.8/site-packages/wandb/sdk/internal/file_stream.py", line 668, in request_with_retry
    logger.warning(
Message: 'requests_with_retry encountered retryable exception: %s. func: %s, args: %s, kwargs: %s'
Arguments: (ProxyError(MaxRetryError("HTTPSConnectionPool(host='api.wandb.ai', port=443): Max retries exceeded with url: /files/satwikdpshrit/radformer/e7mxdf4s/file_stream (Caused by ProxyError('Cannot connect to proxy.', OSError('Tunnel connection failed: 302 Moved Temporarily')))")), functools.partial(<bound method Session.post of <requests.sessions.Session object at 0x7f3794732190>>, timeout=180.0), ('https://api.wandb.ai/files/satwikdpshrit/radformer/e7mxdf4s/file_stream',), {'json': {'complete': False, 'failed': False, 'dropped': 0, 'uploaded': []}})
--- Logging error ---
Traceback (most recent call last):
  File "/home/deepankar/scratch/miniconda3/envs/msa_medical/lib/python3.8/site-packages/urllib3/connectionpool.py", line 712, in urlopen
    self._prepare_proxy(conn)
  File "/home/deepankar/scratch/miniconda3/envs/msa_medical/lib/python3.8/site-packages/urllib3/connectionpool.py", line 1012, in _prepare_proxy
    conn.connect()
  File "/home/deepankar/scratch/miniconda3/envs/msa_medical/lib/python3.8/site-packages/urllib3/connection.py", line 374, in connect
    self._tunnel()
  File "/home/deepankar/scratch/miniconda3/envs/msa_medical/lib/python3.8/http/client.py", line 905, in _tunnel
    raise OSError("Tunnel connection failed: %d %s" % (code,
OSError: Tunnel connection failed: 302 Moved Temporarily

During handling of the above exception, another exception occurred:

Traceback (most recent call last):
  File "/home/deepankar/scratch/miniconda3/envs/msa_medical/lib/python3.8/site-packages/requests/adapters.py", line 440, in send
    resp = conn.urlopen(
  File "/home/deepankar/scratch/miniconda3/envs/msa_medical/lib/python3.8/site-packages/urllib3/connectionpool.py", line 799, in urlopen
    retries = retries.increment(
  File "/home/deepankar/scratch/miniconda3/envs/msa_medical/lib/python3.8/site-packages/urllib3/util/retry.py", line 592, in increment
    raise MaxRetryError(_pool, url, error or ResponseError(cause))
urllib3.exceptions.MaxRetryError: HTTPSConnectionPool(host='api.wandb.ai', port=443): Max retries exceeded with url: /files/satwikdpshrit/radformer/e7mxdf4s/file_stream (Caused by ProxyError('Cannot connect to proxy.', OSError('Tunnel connection failed: 302 Moved Temporarily')))

During handling of the above exception, another exception occurred:

Traceback (most recent call last):
  File "/home/deepankar/scratch/miniconda3/envs/msa_medical/lib/python3.8/site-packages/wandb/sdk/internal/file_stream.py", line 630, in request_with_retry
    response: requests.Response = func(*args, **kwargs)
  File "/home/deepankar/scratch/miniconda3/envs/msa_medical/lib/python3.8/site-packages/requests/sessions.py", line 577, in post
    return self.request('POST', url, data=data, json=json, **kwargs)
  File "/home/deepankar/scratch/miniconda3/envs/msa_medical/lib/python3.8/site-packages/requests/sessions.py", line 529, in request
    resp = self.send(prep, **send_kwargs)
  File "/home/deepankar/scratch/miniconda3/envs/msa_medical/lib/python3.8/site-packages/requests/sessions.py", line 645, in send
    r = adapter.send(request, **kwargs)
  File "/home/deepankar/scratch/miniconda3/envs/msa_medical/lib/python3.8/site-packages/requests/adapters.py", line 513, in send
    raise ProxyError(e, request=request)
requests.exceptions.ProxyError: HTTPSConnectionPool(host='api.wandb.ai', port=443): Max retries exceeded with url: /files/satwikdpshrit/radformer/e7mxdf4s/file_stream (Caused by ProxyError('Cannot connect to proxy.', OSError('Tunnel connection failed: 302 Moved Temporarily')))

During handling of the above exception, another exception occurred:

Traceback (most recent call last):
  File "/home/deepankar/scratch/miniconda3/envs/msa_medical/lib/python3.8/logging/__init__.py", line 1089, in emit
    self.flush()
  File "/home/deepankar/scratch/miniconda3/envs/msa_medical/lib/python3.8/logging/__init__.py", line 1069, in flush
    self.stream.flush()
OSError: [Errno 28] No space left on device
Call stack:
  File "/home/deepankar/scratch/miniconda3/envs/msa_medical/lib/python3.8/threading.py", line 890, in _bootstrap
    self._bootstrap_inner()
  File "/home/deepankar/scratch/miniconda3/envs/msa_medical/lib/python3.8/threading.py", line 932, in _bootstrap_inner
    self.run()
  File "/home/deepankar/scratch/miniconda3/envs/msa_medical/lib/python3.8/threading.py", line 870, in run
    self._target(*self._args, **self._kwargs)
  File "/home/deepankar/scratch/miniconda3/envs/msa_medical/lib/python3.8/site-packages/wandb/sdk/internal/file_stream.py", line 490, in _thread_except_body
    self._thread_body()
  File "/home/deepankar/scratch/miniconda3/envs/msa_medical/lib/python3.8/site-packages/wandb/sdk/internal/file_stream.py", line 461, in _thread_body
    request_with_retry(
  File "/home/deepankar/scratch/miniconda3/envs/msa_medical/lib/python3.8/site-packages/wandb/sdk/internal/file_stream.py", line 668, in request_with_retry
    logger.warning(
Message: 'requests_with_retry encountered retryable exception: %s. func: %s, args: %s, kwargs: %s'
Arguments: (ProxyError(MaxRetryError("HTTPSConnectionPool(host='api.wandb.ai', port=443): Max retries exceeded with url: /files/satwikdpshrit/radformer/e7mxdf4s/file_stream (Caused by ProxyError('Cannot connect to proxy.', OSError('Tunnel connection failed: 302 Moved Temporarily')))")), functools.partial(<bound method Session.post of <requests.sessions.Session object at 0x7f3794732190>>, timeout=180.0), ('https://api.wandb.ai/files/satwikdpshrit/radformer/e7mxdf4s/file_stream',), {'json': {'complete': False, 'failed': False, 'dropped': 0, 'uploaded': []}})
--- Logging error ---
Traceback (most recent call last):
  File "/home/deepankar/scratch/miniconda3/envs/msa_medical/lib/python3.8/site-packages/urllib3/connectionpool.py", line 712, in urlopen
    self._prepare_proxy(conn)
  File "/home/deepankar/scratch/miniconda3/envs/msa_medical/lib/python3.8/site-packages/urllib3/connectionpool.py", line 1012, in _prepare_proxy
    conn.connect()
  File "/home/deepankar/scratch/miniconda3/envs/msa_medical/lib/python3.8/site-packages/urllib3/connection.py", line 374, in connect
    self._tunnel()
  File "/home/deepankar/scratch/miniconda3/envs/msa_medical/lib/python3.8/http/client.py", line 905, in _tunnel
    raise OSError("Tunnel connection failed: %d %s" % (code,
OSError: Tunnel connection failed: 302 Moved Temporarily

During handling of the above exception, another exception occurred:

Traceback (most recent call last):
  File "/home/deepankar/scratch/miniconda3/envs/msa_medical/lib/python3.8/site-packages/requests/adapters.py", line 440, in send
    resp = conn.urlopen(
  File "/home/deepankar/scratch/miniconda3/envs/msa_medical/lib/python3.8/site-packages/urllib3/connectionpool.py", line 799, in urlopen
    retries = retries.increment(
  File "/home/deepankar/scratch/miniconda3/envs/msa_medical/lib/python3.8/site-packages/urllib3/util/retry.py", line 592, in increment
    raise MaxRetryError(_pool, url, error or ResponseError(cause))
urllib3.exceptions.MaxRetryError: HTTPSConnectionPool(host='api.wandb.ai', port=443): Max retries exceeded with url: /files/satwikdpshrit/radformer/e7mxdf4s/file_stream (Caused by ProxyError('Cannot connect to proxy.', OSError('Tunnel connection failed: 302 Moved Temporarily')))

During handling of the above exception, another exception occurred:

Traceback (most recent call last):
  File "/home/deepankar/scratch/miniconda3/envs/msa_medical/lib/python3.8/site-packages/wandb/sdk/internal/file_stream.py", line 630, in request_with_retry
    response: requests.Response = func(*args, **kwargs)
  File "/home/deepankar/scratch/miniconda3/envs/msa_medical/lib/python3.8/site-packages/requests/sessions.py", line 577, in post
    return self.request('POST', url, data=data, json=json, **kwargs)
  File "/home/deepankar/scratch/miniconda3/envs/msa_medical/lib/python3.8/site-packages/requests/sessions.py", line 529, in request
    resp = self.send(prep, **send_kwargs)
  File "/home/deepankar/scratch/miniconda3/envs/msa_medical/lib/python3.8/site-packages/requests/sessions.py", line 645, in send
    r = adapter.send(request, **kwargs)
  File "/home/deepankar/scratch/miniconda3/envs/msa_medical/lib/python3.8/site-packages/requests/adapters.py", line 513, in send
    raise ProxyError(e, request=request)
requests.exceptions.ProxyError: HTTPSConnectionPool(host='api.wandb.ai', port=443): Max retries exceeded with url: /files/satwikdpshrit/radformer/e7mxdf4s/file_stream (Caused by ProxyError('Cannot connect to proxy.', OSError('Tunnel connection failed: 302 Moved Temporarily')))

During handling of the above exception, another exception occurred:

Traceback (most recent call last):
  File "/home/deepankar/scratch/miniconda3/envs/msa_medical/lib/python3.8/logging/__init__.py", line 1089, in emit
    self.flush()
  File "/home/deepankar/scratch/miniconda3/envs/msa_medical/lib/python3.8/logging/__init__.py", line 1069, in flush
    self.stream.flush()
OSError: [Errno 28] No space left on device
Call stack:
  File "/home/deepankar/scratch/miniconda3/envs/msa_medical/lib/python3.8/threading.py", line 890, in _bootstrap
    self._bootstrap_inner()
  File "/home/deepankar/scratch/miniconda3/envs/msa_medical/lib/python3.8/threading.py", line 932, in _bootstrap_inner
    self.run()
  File "/home/deepankar/scratch/miniconda3/envs/msa_medical/lib/python3.8/threading.py", line 870, in run
    self._target(*self._args, **self._kwargs)
  File "/home/deepankar/scratch/miniconda3/envs/msa_medical/lib/python3.8/site-packages/wandb/sdk/internal/file_stream.py", line 490, in _thread_except_body
    self._thread_body()
  File "/home/deepankar/scratch/miniconda3/envs/msa_medical/lib/python3.8/site-packages/wandb/sdk/internal/file_stream.py", line 461, in _thread_body
    request_with_retry(
  File "/home/deepankar/scratch/miniconda3/envs/msa_medical/lib/python3.8/site-packages/wandb/sdk/internal/file_stream.py", line 668, in request_with_retry
    logger.warning(
Message: 'requests_with_retry encountered retryable exception: %s. func: %s, args: %s, kwargs: %s'
Arguments: (ProxyError(MaxRetryError("HTTPSConnectionPool(host='api.wandb.ai', port=443): Max retries exceeded with url: /files/satwikdpshrit/radformer/e7mxdf4s/file_stream (Caused by ProxyError('Cannot connect to proxy.', OSError('Tunnel connection failed: 302 Moved Temporarily')))")), functools.partial(<bound method Session.post of <requests.sessions.Session object at 0x7f3794732190>>, timeout=180.0), ('https://api.wandb.ai/files/satwikdpshrit/radformer/e7mxdf4s/file_stream',), {'json': {'complete': False, 'failed': False, 'dropped': 0, 'uploaded': []}})
--- Logging error ---
Traceback (most recent call last):
  File "/home/deepankar/scratch/miniconda3/envs/msa_medical/lib/python3.8/site-packages/urllib3/connectionpool.py", line 712, in urlopen
    self._prepare_proxy(conn)
  File "/home/deepankar/scratch/miniconda3/envs/msa_medical/lib/python3.8/site-packages/urllib3/connectionpool.py", line 1012, in _prepare_proxy
    conn.connect()
  File "/home/deepankar/scratch/miniconda3/envs/msa_medical/lib/python3.8/site-packages/urllib3/connection.py", line 374, in connect
    self._tunnel()
  File "/home/deepankar/scratch/miniconda3/envs/msa_medical/lib/python3.8/http/client.py", line 905, in _tunnel
    raise OSError("Tunnel connection failed: %d %s" % (code,
OSError: Tunnel connection failed: 302 Moved Temporarily

During handling of the above exception, another exception occurred:

Traceback (most recent call last):
  File "/home/deepankar/scratch/miniconda3/envs/msa_medical/lib/python3.8/site-packages/requests/adapters.py", line 440, in send
    resp = conn.urlopen(
  File "/home/deepankar/scratch/miniconda3/envs/msa_medical/lib/python3.8/site-packages/urllib3/connectionpool.py", line 799, in urlopen
    retries = retries.increment(
  File "/home/deepankar/scratch/miniconda3/envs/msa_medical/lib/python3.8/site-packages/urllib3/util/retry.py", line 592, in increment
    raise MaxRetryError(_pool, url, error or ResponseError(cause))
urllib3.exceptions.MaxRetryError: HTTPSConnectionPool(host='api.wandb.ai', port=443): Max retries exceeded with url: /files/satwikdpshrit/radformer/e7mxdf4s/file_stream (Caused by ProxyError('Cannot connect to proxy.', OSError('Tunnel connection failed: 302 Moved Temporarily')))

During handling of the above exception, another exception occurred:

Traceback (most recent call last):
  File "/home/deepankar/scratch/miniconda3/envs/msa_medical/lib/python3.8/site-packages/wandb/sdk/internal/file_stream.py", line 630, in request_with_retry
    response: requests.Response = func(*args, **kwargs)
  File "/home/deepankar/scratch/miniconda3/envs/msa_medical/lib/python3.8/site-packages/requests/sessions.py", line 577, in post
    return self.request('POST', url, data=data, json=json, **kwargs)
  File "/home/deepankar/scratch/miniconda3/envs/msa_medical/lib/python3.8/site-packages/requests/sessions.py", line 529, in request
    resp = self.send(prep, **send_kwargs)
  File "/home/deepankar/scratch/miniconda3/envs/msa_medical/lib/python3.8/site-packages/requests/sessions.py", line 645, in send
    r = adapter.send(request, **kwargs)
  File "/home/deepankar/scratch/miniconda3/envs/msa_medical/lib/python3.8/site-packages/requests/adapters.py", line 513, in send
    raise ProxyError(e, request=request)
requests.exceptions.ProxyError: HTTPSConnectionPool(host='api.wandb.ai', port=443): Max retries exceeded with url: /files/satwikdpshrit/radformer/e7mxdf4s/file_stream (Caused by ProxyError('Cannot connect to proxy.', OSError('Tunnel connection failed: 302 Moved Temporarily')))

During handling of the above exception, another exception occurred:

Traceback (most recent call last):
  File "/home/deepankar/scratch/miniconda3/envs/msa_medical/lib/python3.8/logging/__init__.py", line 1089, in emit
    self.flush()
  File "/home/deepankar/scratch/miniconda3/envs/msa_medical/lib/python3.8/logging/__init__.py", line 1069, in flush
    self.stream.flush()
OSError: [Errno 28] No space left on device
Call stack:
  File "/home/deepankar/scratch/miniconda3/envs/msa_medical/lib/python3.8/threading.py", line 890, in _bootstrap
    self._bootstrap_inner()
  File "/home/deepankar/scratch/miniconda3/envs/msa_medical/lib/python3.8/threading.py", line 932, in _bootstrap_inner
    self.run()
  File "/home/deepankar/scratch/miniconda3/envs/msa_medical/lib/python3.8/threading.py", line 870, in run
    self._target(*self._args, **self._kwargs)
  File "/home/deepankar/scratch/miniconda3/envs/msa_medical/lib/python3.8/site-packages/wandb/sdk/internal/file_stream.py", line 490, in _thread_except_body
    self._thread_body()
  File "/home/deepankar/scratch/miniconda3/envs/msa_medical/lib/python3.8/site-packages/wandb/sdk/internal/file_stream.py", line 461, in _thread_body
    request_with_retry(
  File "/home/deepankar/scratch/miniconda3/envs/msa_medical/lib/python3.8/site-packages/wandb/sdk/internal/file_stream.py", line 668, in request_with_retry
    logger.warning(
Message: 'requests_with_retry encountered retryable exception: %s. func: %s, args: %s, kwargs: %s'
Arguments: (ProxyError(MaxRetryError("HTTPSConnectionPool(host='api.wandb.ai', port=443): Max retries exceeded with url: /files/satwikdpshrit/radformer/e7mxdf4s/file_stream (Caused by ProxyError('Cannot connect to proxy.', OSError('Tunnel connection failed: 302 Moved Temporarily')))")), functools.partial(<bound method Session.post of <requests.sessions.Session object at 0x7f3794732190>>, timeout=180.0), ('https://api.wandb.ai/files/satwikdpshrit/radformer/e7mxdf4s/file_stream',), {'json': {'complete': False, 'failed': False, 'dropped': 0, 'uploaded': []}})
--- Logging error ---
Traceback (most recent call last):
  File "/home/deepankar/scratch/miniconda3/envs/msa_medical/lib/python3.8/site-packages/urllib3/connectionpool.py", line 712, in urlopen
    self._prepare_proxy(conn)
  File "/home/deepankar/scratch/miniconda3/envs/msa_medical/lib/python3.8/site-packages/urllib3/connectionpool.py", line 1012, in _prepare_proxy
    conn.connect()
  File "/home/deepankar/scratch/miniconda3/envs/msa_medical/lib/python3.8/site-packages/urllib3/connection.py", line 374, in connect
    self._tunnel()
  File "/home/deepankar/scratch/miniconda3/envs/msa_medical/lib/python3.8/http/client.py", line 905, in _tunnel
    raise OSError("Tunnel connection failed: %d %s" % (code,
OSError: Tunnel connection failed: 302 Moved Temporarily

During handling of the above exception, another exception occurred:

Traceback (most recent call last):
  File "/home/deepankar/scratch/miniconda3/envs/msa_medical/lib/python3.8/site-packages/requests/adapters.py", line 440, in send
    resp = conn.urlopen(
  File "/home/deepankar/scratch/miniconda3/envs/msa_medical/lib/python3.8/site-packages/urllib3/connectionpool.py", line 799, in urlopen
    retries = retries.increment(
  File "/home/deepankar/scratch/miniconda3/envs/msa_medical/lib/python3.8/site-packages/urllib3/util/retry.py", line 592, in increment
    raise MaxRetryError(_pool, url, error or ResponseError(cause))
urllib3.exceptions.MaxRetryError: HTTPSConnectionPool(host='api.wandb.ai', port=443): Max retries exceeded with url: /files/satwikdpshrit/radformer/e7mxdf4s/file_stream (Caused by ProxyError('Cannot connect to proxy.', OSError('Tunnel connection failed: 302 Moved Temporarily')))

During handling of the above exception, another exception occurred:

Traceback (most recent call last):
  File "/home/deepankar/scratch/miniconda3/envs/msa_medical/lib/python3.8/site-packages/wandb/sdk/internal/file_stream.py", line 630, in request_with_retry
    response: requests.Response = func(*args, **kwargs)
  File "/home/deepankar/scratch/miniconda3/envs/msa_medical/lib/python3.8/site-packages/requests/sessions.py", line 577, in post
    return self.request('POST', url, data=data, json=json, **kwargs)
  File "/home/deepankar/scratch/miniconda3/envs/msa_medical/lib/python3.8/site-packages/requests/sessions.py", line 529, in request
    resp = self.send(prep, **send_kwargs)
  File "/home/deepankar/scratch/miniconda3/envs/msa_medical/lib/python3.8/site-packages/requests/sessions.py", line 645, in send
    r = adapter.send(request, **kwargs)
  File "/home/deepankar/scratch/miniconda3/envs/msa_medical/lib/python3.8/site-packages/requests/adapters.py", line 513, in send
    raise ProxyError(e, request=request)
requests.exceptions.ProxyError: HTTPSConnectionPool(host='api.wandb.ai', port=443): Max retries exceeded with url: /files/satwikdpshrit/radformer/e7mxdf4s/file_stream (Caused by ProxyError('Cannot connect to proxy.', OSError('Tunnel connection failed: 302 Moved Temporarily')))

During handling of the above exception, another exception occurred:

Traceback (most recent call last):
  File "/home/deepankar/scratch/miniconda3/envs/msa_medical/lib/python3.8/logging/__init__.py", line 1089, in emit
    self.flush()
  File "/home/deepankar/scratch/miniconda3/envs/msa_medical/lib/python3.8/logging/__init__.py", line 1069, in flush
    self.stream.flush()
OSError: [Errno 28] No space left on device
Call stack:
  File "/home/deepankar/scratch/miniconda3/envs/msa_medical/lib/python3.8/threading.py", line 890, in _bootstrap
    self._bootstrap_inner()
  File "/home/deepankar/scratch/miniconda3/envs/msa_medical/lib/python3.8/threading.py", line 932, in _bootstrap_inner
    self.run()
  File "/home/deepankar/scratch/miniconda3/envs/msa_medical/lib/python3.8/threading.py", line 870, in run
    self._target(*self._args, **self._kwargs)
  File "/home/deepankar/scratch/miniconda3/envs/msa_medical/lib/python3.8/site-packages/wandb/sdk/internal/file_stream.py", line 490, in _thread_except_body
    self._thread_body()
  File "/home/deepankar/scratch/miniconda3/envs/msa_medical/lib/python3.8/site-packages/wandb/sdk/internal/file_stream.py", line 461, in _thread_body
    request_with_retry(
  File "/home/deepankar/scratch/miniconda3/envs/msa_medical/lib/python3.8/site-packages/wandb/sdk/internal/file_stream.py", line 668, in request_with_retry
    logger.warning(
Message: 'requests_with_retry encountered retryable exception: %s. func: %s, args: %s, kwargs: %s'
Arguments: (ProxyError(MaxRetryError("HTTPSConnectionPool(host='api.wandb.ai', port=443): Max retries exceeded with url: /files/satwikdpshrit/radformer/e7mxdf4s/file_stream (Caused by ProxyError('Cannot connect to proxy.', OSError('Tunnel connection failed: 302 Moved Temporarily')))")), functools.partial(<bound method Session.post of <requests.sessions.Session object at 0x7f3794732190>>, timeout=180.0), ('https://api.wandb.ai/files/satwikdpshrit/radformer/e7mxdf4s/file_stream',), {'json': {'complete': False, 'failed': False, 'dropped': 0, 'uploaded': []}})
--- Logging error ---
Traceback (most recent call last):
  File "/home/deepankar/scratch/miniconda3/envs/msa_medical/lib/python3.8/site-packages/urllib3/connectionpool.py", line 712, in urlopen
    self._prepare_proxy(conn)
  File "/home/deepankar/scratch/miniconda3/envs/msa_medical/lib/python3.8/site-packages/urllib3/connectionpool.py", line 1012, in _prepare_proxy
    conn.connect()
  File "/home/deepankar/scratch/miniconda3/envs/msa_medical/lib/python3.8/site-packages/urllib3/connection.py", line 374, in connect
    self._tunnel()
  File "/home/deepankar/scratch/miniconda3/envs/msa_medical/lib/python3.8/http/client.py", line 905, in _tunnel
    raise OSError("Tunnel connection failed: %d %s" % (code,
OSError: Tunnel connection failed: 302 Moved Temporarily

During handling of the above exception, another exception occurred:

Traceback (most recent call last):
  File "/home/deepankar/scratch/miniconda3/envs/msa_medical/lib/python3.8/site-packages/requests/adapters.py", line 440, in send
    resp = conn.urlopen(
  File "/home/deepankar/scratch/miniconda3/envs/msa_medical/lib/python3.8/site-packages/urllib3/connectionpool.py", line 799, in urlopen
    retries = retries.increment(
  File "/home/deepankar/scratch/miniconda3/envs/msa_medical/lib/python3.8/site-packages/urllib3/util/retry.py", line 592, in increment
    raise MaxRetryError(_pool, url, error or ResponseError(cause))
urllib3.exceptions.MaxRetryError: HTTPSConnectionPool(host='api.wandb.ai', port=443): Max retries exceeded with url: /files/satwikdpshrit/radformer/e7mxdf4s/file_stream (Caused by ProxyError('Cannot connect to proxy.', OSError('Tunnel connection failed: 302 Moved Temporarily')))

During handling of the above exception, another exception occurred:

Traceback (most recent call last):
  File "/home/deepankar/scratch/miniconda3/envs/msa_medical/lib/python3.8/site-packages/wandb/sdk/internal/file_stream.py", line 630, in request_with_retry
    response: requests.Response = func(*args, **kwargs)
  File "/home/deepankar/scratch/miniconda3/envs/msa_medical/lib/python3.8/site-packages/requests/sessions.py", line 577, in post
    return self.request('POST', url, data=data, json=json, **kwargs)
  File "/home/deepankar/scratch/miniconda3/envs/msa_medical/lib/python3.8/site-packages/requests/sessions.py", line 529, in request
    resp = self.send(prep, **send_kwargs)
  File "/home/deepankar/scratch/miniconda3/envs/msa_medical/lib/python3.8/site-packages/requests/sessions.py", line 645, in send
    r = adapter.send(request, **kwargs)
  File "/home/deepankar/scratch/miniconda3/envs/msa_medical/lib/python3.8/site-packages/requests/adapters.py", line 513, in send
    raise ProxyError(e, request=request)
requests.exceptions.ProxyError: HTTPSConnectionPool(host='api.wandb.ai', port=443): Max retries exceeded with url: /files/satwikdpshrit/radformer/e7mxdf4s/file_stream (Caused by ProxyError('Cannot connect to proxy.', OSError('Tunnel connection failed: 302 Moved Temporarily')))

During handling of the above exception, another exception occurred:

Traceback (most recent call last):
  File "/home/deepankar/scratch/miniconda3/envs/msa_medical/lib/python3.8/logging/__init__.py", line 1089, in emit
    self.flush()
  File "/home/deepankar/scratch/miniconda3/envs/msa_medical/lib/python3.8/logging/__init__.py", line 1069, in flush
    self.stream.flush()
OSError: [Errno 28] No space left on device
Call stack:
  File "/home/deepankar/scratch/miniconda3/envs/msa_medical/lib/python3.8/threading.py", line 890, in _bootstrap
    self._bootstrap_inner()
  File "/home/deepankar/scratch/miniconda3/envs/msa_medical/lib/python3.8/threading.py", line 932, in _bootstrap_inner
    self.run()
  File "/home/deepankar/scratch/miniconda3/envs/msa_medical/lib/python3.8/threading.py", line 870, in run
    self._target(*self._args, **self._kwargs)
  File "/home/deepankar/scratch/miniconda3/envs/msa_medical/lib/python3.8/site-packages/wandb/sdk/internal/file_stream.py", line 490, in _thread_except_body
    self._thread_body()
  File "/home/deepankar/scratch/miniconda3/envs/msa_medical/lib/python3.8/site-packages/wandb/sdk/internal/file_stream.py", line 461, in _thread_body
    request_with_retry(
  File "/home/deepankar/scratch/miniconda3/envs/msa_medical/lib/python3.8/site-packages/wandb/sdk/internal/file_stream.py", line 668, in request_with_retry
    logger.warning(
Message: 'requests_with_retry encountered retryable exception: %s. func: %s, args: %s, kwargs: %s'
Arguments: (ProxyError(MaxRetryError("HTTPSConnectionPool(host='api.wandb.ai', port=443): Max retries exceeded with url: /files/satwikdpshrit/radformer/e7mxdf4s/file_stream (Caused by ProxyError('Cannot connect to proxy.', OSError('Tunnel connection failed: 302 Moved Temporarily')))")), functools.partial(<bound method Session.post of <requests.sessions.Session object at 0x7f3794732190>>, timeout=180.0), ('https://api.wandb.ai/files/satwikdpshrit/radformer/e7mxdf4s/file_stream',), {'json': {'complete': False, 'failed': False, 'dropped': 0, 'uploaded': []}})
--- Logging error ---
Traceback (most recent call last):
  File "/home/deepankar/scratch/miniconda3/envs/msa_medical/lib/python3.8/site-packages/urllib3/connectionpool.py", line 712, in urlopen
    self._prepare_proxy(conn)
  File "/home/deepankar/scratch/miniconda3/envs/msa_medical/lib/python3.8/site-packages/urllib3/connectionpool.py", line 1012, in _prepare_proxy
    conn.connect()
  File "/home/deepankar/scratch/miniconda3/envs/msa_medical/lib/python3.8/site-packages/urllib3/connection.py", line 374, in connect
    self._tunnel()
  File "/home/deepankar/scratch/miniconda3/envs/msa_medical/lib/python3.8/http/client.py", line 905, in _tunnel
    raise OSError("Tunnel connection failed: %d %s" % (code,
OSError: Tunnel connection failed: 302 Moved Temporarily

During handling of the above exception, another exception occurred:

Traceback (most recent call last):
  File "/home/deepankar/scratch/miniconda3/envs/msa_medical/lib/python3.8/site-packages/requests/adapters.py", line 440, in send
    resp = conn.urlopen(
  File "/home/deepankar/scratch/miniconda3/envs/msa_medical/lib/python3.8/site-packages/urllib3/connectionpool.py", line 799, in urlopen
    retries = retries.increment(
  File "/home/deepankar/scratch/miniconda3/envs/msa_medical/lib/python3.8/site-packages/urllib3/util/retry.py", line 592, in increment
    raise MaxRetryError(_pool, url, error or ResponseError(cause))
urllib3.exceptions.MaxRetryError: HTTPSConnectionPool(host='api.wandb.ai', port=443): Max retries exceeded with url: /files/satwikdpshrit/radformer/e7mxdf4s/file_stream (Caused by ProxyError('Cannot connect to proxy.', OSError('Tunnel connection failed: 302 Moved Temporarily')))

During handling of the above exception, another exception occurred:

Traceback (most recent call last):
  File "/home/deepankar/scratch/miniconda3/envs/msa_medical/lib/python3.8/site-packages/wandb/sdk/internal/file_stream.py", line 630, in request_with_retry
    response: requests.Response = func(*args, **kwargs)
  File "/home/deepankar/scratch/miniconda3/envs/msa_medical/lib/python3.8/site-packages/requests/sessions.py", line 577, in post
    return self.request('POST', url, data=data, json=json, **kwargs)
  File "/home/deepankar/scratch/miniconda3/envs/msa_medical/lib/python3.8/site-packages/requests/sessions.py", line 529, in request
    resp = self.send(prep, **send_kwargs)
  File "/home/deepankar/scratch/miniconda3/envs/msa_medical/lib/python3.8/site-packages/requests/sessions.py", line 645, in send
    r = adapter.send(request, **kwargs)
  File "/home/deepankar/scratch/miniconda3/envs/msa_medical/lib/python3.8/site-packages/requests/adapters.py", line 513, in send
    raise ProxyError(e, request=request)
requests.exceptions.ProxyError: HTTPSConnectionPool(host='api.wandb.ai', port=443): Max retries exceeded with url: /files/satwikdpshrit/radformer/e7mxdf4s/file_stream (Caused by ProxyError('Cannot connect to proxy.', OSError('Tunnel connection failed: 302 Moved Temporarily')))

During handling of the above exception, another exception occurred:

Traceback (most recent call last):
  File "/home/deepankar/scratch/miniconda3/envs/msa_medical/lib/python3.8/logging/__init__.py", line 1089, in emit
    self.flush()
  File "/home/deepankar/scratch/miniconda3/envs/msa_medical/lib/python3.8/logging/__init__.py", line 1069, in flush
    self.stream.flush()
OSError: [Errno 28] No space left on device
Call stack:
  File "/home/deepankar/scratch/miniconda3/envs/msa_medical/lib/python3.8/threading.py", line 890, in _bootstrap
    self._bootstrap_inner()
  File "/home/deepankar/scratch/miniconda3/envs/msa_medical/lib/python3.8/threading.py", line 932, in _bootstrap_inner
    self.run()
  File "/home/deepankar/scratch/miniconda3/envs/msa_medical/lib/python3.8/threading.py", line 870, in run
    self._target(*self._args, **self._kwargs)
  File "/home/deepankar/scratch/miniconda3/envs/msa_medical/lib/python3.8/site-packages/wandb/sdk/internal/file_stream.py", line 490, in _thread_except_body
    self._thread_body()
  File "/home/deepankar/scratch/miniconda3/envs/msa_medical/lib/python3.8/site-packages/wandb/sdk/internal/file_stream.py", line 461, in _thread_body
    request_with_retry(
  File "/home/deepankar/scratch/miniconda3/envs/msa_medical/lib/python3.8/site-packages/wandb/sdk/internal/file_stream.py", line 668, in request_with_retry
    logger.warning(
Message: 'requests_with_retry encountered retryable exception: %s. func: %s, args: %s, kwargs: %s'
Arguments: (ProxyError(MaxRetryError("HTTPSConnectionPool(host='api.wandb.ai', port=443): Max retries exceeded with url: /files/satwikdpshrit/radformer/e7mxdf4s/file_stream (Caused by ProxyError('Cannot connect to proxy.', OSError('Tunnel connection failed: 302 Moved Temporarily')))")), functools.partial(<bound method Session.post of <requests.sessions.Session object at 0x7f3794732190>>, timeout=180.0), ('https://api.wandb.ai/files/satwikdpshrit/radformer/e7mxdf4s/file_stream',), {'json': {'complete': False, 'failed': False, 'dropped': 0, 'uploaded': []}})
--- Logging error ---
Traceback (most recent call last):
  File "/home/deepankar/scratch/miniconda3/envs/msa_medical/lib/python3.8/site-packages/urllib3/connectionpool.py", line 712, in urlopen
    self._prepare_proxy(conn)
  File "/home/deepankar/scratch/miniconda3/envs/msa_medical/lib/python3.8/site-packages/urllib3/connectionpool.py", line 1012, in _prepare_proxy
    conn.connect()
  File "/home/deepankar/scratch/miniconda3/envs/msa_medical/lib/python3.8/site-packages/urllib3/connection.py", line 374, in connect
    self._tunnel()
  File "/home/deepankar/scratch/miniconda3/envs/msa_medical/lib/python3.8/http/client.py", line 905, in _tunnel
    raise OSError("Tunnel connection failed: %d %s" % (code,
OSError: Tunnel connection failed: 302 Moved Temporarily

During handling of the above exception, another exception occurred:

Traceback (most recent call last):
  File "/home/deepankar/scratch/miniconda3/envs/msa_medical/lib/python3.8/site-packages/requests/adapters.py", line 440, in send
    resp = conn.urlopen(
  File "/home/deepankar/scratch/miniconda3/envs/msa_medical/lib/python3.8/site-packages/urllib3/connectionpool.py", line 799, in urlopen
    retries = retries.increment(
  File "/home/deepankar/scratch/miniconda3/envs/msa_medical/lib/python3.8/site-packages/urllib3/util/retry.py", line 592, in increment
    raise MaxRetryError(_pool, url, error or ResponseError(cause))
urllib3.exceptions.MaxRetryError: HTTPSConnectionPool(host='api.wandb.ai', port=443): Max retries exceeded with url: /files/satwikdpshrit/radformer/e7mxdf4s/file_stream (Caused by ProxyError('Cannot connect to proxy.', OSError('Tunnel connection failed: 302 Moved Temporarily')))

During handling of the above exception, another exception occurred:

Traceback (most recent call last):
  File "/home/deepankar/scratch/miniconda3/envs/msa_medical/lib/python3.8/site-packages/wandb/sdk/internal/file_stream.py", line 630, in request_with_retry
    response: requests.Response = func(*args, **kwargs)
  File "/home/deepankar/scratch/miniconda3/envs/msa_medical/lib/python3.8/site-packages/requests/sessions.py", line 577, in post
    return self.request('POST', url, data=data, json=json, **kwargs)
  File "/home/deepankar/scratch/miniconda3/envs/msa_medical/lib/python3.8/site-packages/requests/sessions.py", line 529, in request
    resp = self.send(prep, **send_kwargs)
  File "/home/deepankar/scratch/miniconda3/envs/msa_medical/lib/python3.8/site-packages/requests/sessions.py", line 645, in send
    r = adapter.send(request, **kwargs)
  File "/home/deepankar/scratch/miniconda3/envs/msa_medical/lib/python3.8/site-packages/requests/adapters.py", line 513, in send
    raise ProxyError(e, request=request)
requests.exceptions.ProxyError: HTTPSConnectionPool(host='api.wandb.ai', port=443): Max retries exceeded with url: /files/satwikdpshrit/radformer/e7mxdf4s/file_stream (Caused by ProxyError('Cannot connect to proxy.', OSError('Tunnel connection failed: 302 Moved Temporarily')))

During handling of the above exception, another exception occurred:

Traceback (most recent call last):
  File "/home/deepankar/scratch/miniconda3/envs/msa_medical/lib/python3.8/logging/__init__.py", line 1089, in emit
    self.flush()
  File "/home/deepankar/scratch/miniconda3/envs/msa_medical/lib/python3.8/logging/__init__.py", line 1069, in flush
    self.stream.flush()
OSError: [Errno 28] No space left on device
Call stack:
  File "/home/deepankar/scratch/miniconda3/envs/msa_medical/lib/python3.8/threading.py", line 890, in _bootstrap
    self._bootstrap_inner()
  File "/home/deepankar/scratch/miniconda3/envs/msa_medical/lib/python3.8/threading.py", line 932, in _bootstrap_inner
    self.run()
  File "/home/deepankar/scratch/miniconda3/envs/msa_medical/lib/python3.8/threading.py", line 870, in run
    self._target(*self._args, **self._kwargs)
  File "/home/deepankar/scratch/miniconda3/envs/msa_medical/lib/python3.8/site-packages/wandb/sdk/internal/file_stream.py", line 490, in _thread_except_body
    self._thread_body()
  File "/home/deepankar/scratch/miniconda3/envs/msa_medical/lib/python3.8/site-packages/wandb/sdk/internal/file_stream.py", line 461, in _thread_body
    request_with_retry(
  File "/home/deepankar/scratch/miniconda3/envs/msa_medical/lib/python3.8/site-packages/wandb/sdk/internal/file_stream.py", line 668, in request_with_retry
    logger.warning(
Message: 'requests_with_retry encountered retryable exception: %s. func: %s, args: %s, kwargs: %s'
Arguments: (ProxyError(MaxRetryError("HTTPSConnectionPool(host='api.wandb.ai', port=443): Max retries exceeded with url: /files/satwikdpshrit/radformer/e7mxdf4s/file_stream (Caused by ProxyError('Cannot connect to proxy.', OSError('Tunnel connection failed: 302 Moved Temporarily')))")), functools.partial(<bound method Session.post of <requests.sessions.Session object at 0x7f3794732190>>, timeout=180.0), ('https://api.wandb.ai/files/satwikdpshrit/radformer/e7mxdf4s/file_stream',), {'json': {'complete': False, 'failed': False, 'dropped': 0, 'uploaded': []}})
--- Logging error ---
Traceback (most recent call last):
  File "/home/deepankar/scratch/miniconda3/envs/msa_medical/lib/python3.8/site-packages/urllib3/connectionpool.py", line 712, in urlopen
    self._prepare_proxy(conn)
  File "/home/deepankar/scratch/miniconda3/envs/msa_medical/lib/python3.8/site-packages/urllib3/connectionpool.py", line 1012, in _prepare_proxy
    conn.connect()
  File "/home/deepankar/scratch/miniconda3/envs/msa_medical/lib/python3.8/site-packages/urllib3/connection.py", line 374, in connect
    self._tunnel()
  File "/home/deepankar/scratch/miniconda3/envs/msa_medical/lib/python3.8/http/client.py", line 905, in _tunnel
    raise OSError("Tunnel connection failed: %d %s" % (code,
OSError: Tunnel connection failed: 302 Moved Temporarily

During handling of the above exception, another exception occurred:

Traceback (most recent call last):
  File "/home/deepankar/scratch/miniconda3/envs/msa_medical/lib/python3.8/site-packages/requests/adapters.py", line 440, in send
    resp = conn.urlopen(
  File "/home/deepankar/scratch/miniconda3/envs/msa_medical/lib/python3.8/site-packages/urllib3/connectionpool.py", line 799, in urlopen
    retries = retries.increment(
  File "/home/deepankar/scratch/miniconda3/envs/msa_medical/lib/python3.8/site-packages/urllib3/util/retry.py", line 592, in increment
    raise MaxRetryError(_pool, url, error or ResponseError(cause))
urllib3.exceptions.MaxRetryError: HTTPSConnectionPool(host='api.wandb.ai', port=443): Max retries exceeded with url: /files/satwikdpshrit/radformer/e7mxdf4s/file_stream (Caused by ProxyError('Cannot connect to proxy.', OSError('Tunnel connection failed: 302 Moved Temporarily')))

During handling of the above exception, another exception occurred:

Traceback (most recent call last):
  File "/home/deepankar/scratch/miniconda3/envs/msa_medical/lib/python3.8/site-packages/wandb/sdk/internal/file_stream.py", line 630, in request_with_retry
    response: requests.Response = func(*args, **kwargs)
  File "/home/deepankar/scratch/miniconda3/envs/msa_medical/lib/python3.8/site-packages/requests/sessions.py", line 577, in post
    return self.request('POST', url, data=data, json=json, **kwargs)
  File "/home/deepankar/scratch/miniconda3/envs/msa_medical/lib/python3.8/site-packages/requests/sessions.py", line 529, in request
    resp = self.send(prep, **send_kwargs)
  File "/home/deepankar/scratch/miniconda3/envs/msa_medical/lib/python3.8/site-packages/requests/sessions.py", line 645, in send
    r = adapter.send(request, **kwargs)
  File "/home/deepankar/scratch/miniconda3/envs/msa_medical/lib/python3.8/site-packages/requests/adapters.py", line 513, in send
    raise ProxyError(e, request=request)
requests.exceptions.ProxyError: HTTPSConnectionPool(host='api.wandb.ai', port=443): Max retries exceeded with url: /files/satwikdpshrit/radformer/e7mxdf4s/file_stream (Caused by ProxyError('Cannot connect to proxy.', OSError('Tunnel connection failed: 302 Moved Temporarily')))

During handling of the above exception, another exception occurred:

Traceback (most recent call last):
  File "/home/deepankar/scratch/miniconda3/envs/msa_medical/lib/python3.8/logging/__init__.py", line 1089, in emit
    self.flush()
  File "/home/deepankar/scratch/miniconda3/envs/msa_medical/lib/python3.8/logging/__init__.py", line 1069, in flush
    self.stream.flush()
OSError: [Errno 28] No space left on device
Call stack:
  File "/home/deepankar/scratch/miniconda3/envs/msa_medical/lib/python3.8/threading.py", line 890, in _bootstrap
    self._bootstrap_inner()
  File "/home/deepankar/scratch/miniconda3/envs/msa_medical/lib/python3.8/threading.py", line 932, in _bootstrap_inner
    self.run()
  File "/home/deepankar/scratch/miniconda3/envs/msa_medical/lib/python3.8/threading.py", line 870, in run
    self._target(*self._args, **self._kwargs)
  File "/home/deepankar/scratch/miniconda3/envs/msa_medical/lib/python3.8/site-packages/wandb/sdk/internal/file_stream.py", line 490, in _thread_except_body
    self._thread_body()
  File "/home/deepankar/scratch/miniconda3/envs/msa_medical/lib/python3.8/site-packages/wandb/sdk/internal/file_stream.py", line 461, in _thread_body
    request_with_retry(
  File "/home/deepankar/scratch/miniconda3/envs/msa_medical/lib/python3.8/site-packages/wandb/sdk/internal/file_stream.py", line 668, in request_with_retry
    logger.warning(
Message: 'requests_with_retry encountered retryable exception: %s. func: %s, args: %s, kwargs: %s'
Arguments: (ProxyError(MaxRetryError("HTTPSConnectionPool(host='api.wandb.ai', port=443): Max retries exceeded with url: /files/satwikdpshrit/radformer/e7mxdf4s/file_stream (Caused by ProxyError('Cannot connect to proxy.', OSError('Tunnel connection failed: 302 Moved Temporarily')))")), functools.partial(<bound method Session.post of <requests.sessions.Session object at 0x7f3794732190>>, timeout=180.0), ('https://api.wandb.ai/files/satwikdpshrit/radformer/e7mxdf4s/file_stream',), {'json': {'complete': False, 'failed': False, 'dropped': 0, 'uploaded': []}})
--- Logging error ---
Traceback (most recent call last):
  File "/home/deepankar/scratch/miniconda3/envs/msa_medical/lib/python3.8/site-packages/urllib3/connectionpool.py", line 712, in urlopen
    self._prepare_proxy(conn)
  File "/home/deepankar/scratch/miniconda3/envs/msa_medical/lib/python3.8/site-packages/urllib3/connectionpool.py", line 1012, in _prepare_proxy
    conn.connect()
  File "/home/deepankar/scratch/miniconda3/envs/msa_medical/lib/python3.8/site-packages/urllib3/connection.py", line 374, in connect
    self._tunnel()
  File "/home/deepankar/scratch/miniconda3/envs/msa_medical/lib/python3.8/http/client.py", line 905, in _tunnel
    raise OSError("Tunnel connection failed: %d %s" % (code,
OSError: Tunnel connection failed: 302 Moved Temporarily

During handling of the above exception, another exception occurred:

Traceback (most recent call last):
  File "/home/deepankar/scratch/miniconda3/envs/msa_medical/lib/python3.8/site-packages/requests/adapters.py", line 440, in send
    resp = conn.urlopen(
  File "/home/deepankar/scratch/miniconda3/envs/msa_medical/lib/python3.8/site-packages/urllib3/connectionpool.py", line 799, in urlopen
    retries = retries.increment(
  File "/home/deepankar/scratch/miniconda3/envs/msa_medical/lib/python3.8/site-packages/urllib3/util/retry.py", line 592, in increment
    raise MaxRetryError(_pool, url, error or ResponseError(cause))
urllib3.exceptions.MaxRetryError: HTTPSConnectionPool(host='api.wandb.ai', port=443): Max retries exceeded with url: /files/satwikdpshrit/radformer/e7mxdf4s/file_stream (Caused by ProxyError('Cannot connect to proxy.', OSError('Tunnel connection failed: 302 Moved Temporarily')))

During handling of the above exception, another exception occurred:

Traceback (most recent call last):
  File "/home/deepankar/scratch/miniconda3/envs/msa_medical/lib/python3.8/site-packages/wandb/sdk/internal/file_stream.py", line 630, in request_with_retry
    response: requests.Response = func(*args, **kwargs)
  File "/home/deepankar/scratch/miniconda3/envs/msa_medical/lib/python3.8/site-packages/requests/sessions.py", line 577, in post
    return self.request('POST', url, data=data, json=json, **kwargs)
  File "/home/deepankar/scratch/miniconda3/envs/msa_medical/lib/python3.8/site-packages/requests/sessions.py", line 529, in request
    resp = self.send(prep, **send_kwargs)
  File "/home/deepankar/scratch/miniconda3/envs/msa_medical/lib/python3.8/site-packages/requests/sessions.py", line 645, in send
    r = adapter.send(request, **kwargs)
  File "/home/deepankar/scratch/miniconda3/envs/msa_medical/lib/python3.8/site-packages/requests/adapters.py", line 513, in send
    raise ProxyError(e, request=request)
requests.exceptions.ProxyError: HTTPSConnectionPool(host='api.wandb.ai', port=443): Max retries exceeded with url: /files/satwikdpshrit/radformer/e7mxdf4s/file_stream (Caused by ProxyError('Cannot connect to proxy.', OSError('Tunnel connection failed: 302 Moved Temporarily')))

During handling of the above exception, another exception occurred:

Traceback (most recent call last):
  File "/home/deepankar/scratch/miniconda3/envs/msa_medical/lib/python3.8/logging/__init__.py", line 1089, in emit
    self.flush()
  File "/home/deepankar/scratch/miniconda3/envs/msa_medical/lib/python3.8/logging/__init__.py", line 1069, in flush
    self.stream.flush()
OSError: [Errno 28] No space left on device
Call stack:
  File "/home/deepankar/scratch/miniconda3/envs/msa_medical/lib/python3.8/threading.py", line 890, in _bootstrap
    self._bootstrap_inner()
  File "/home/deepankar/scratch/miniconda3/envs/msa_medical/lib/python3.8/threading.py", line 932, in _bootstrap_inner
    self.run()
  File "/home/deepankar/scratch/miniconda3/envs/msa_medical/lib/python3.8/threading.py", line 870, in run
    self._target(*self._args, **self._kwargs)
  File "/home/deepankar/scratch/miniconda3/envs/msa_medical/lib/python3.8/site-packages/wandb/sdk/internal/file_stream.py", line 490, in _thread_except_body
    self._thread_body()
  File "/home/deepankar/scratch/miniconda3/envs/msa_medical/lib/python3.8/site-packages/wandb/sdk/internal/file_stream.py", line 461, in _thread_body
    request_with_retry(
  File "/home/deepankar/scratch/miniconda3/envs/msa_medical/lib/python3.8/site-packages/wandb/sdk/internal/file_stream.py", line 668, in request_with_retry
    logger.warning(
Message: 'requests_with_retry encountered retr